Workbook

Sheet Abundances
A1: Feature_ID | B1: K107dI | C1: K069dI | D1: K105dI | E1: K064dI | F1: K063dI | G1: K101dI | H1: K106dI | I1: K113dI | J1: K062dI | K1: K109dI | L1: K074dI | M1: K114dI | N1: K103dI | O1: K070dI | P1: K079dI | Q1: K115dI | R1: K120dI | S1: K080dI | T1: K116dI | U1: K067dI | V1: K077dI | W1: K073dI | X1: K071dI | Y1: K117dI | Z1: K064dH | AA1: K071dH | AB1: K106dH | AC1: K107dH | AD1: K116dH | AE1: K067dH | AF1: K120dH | AG1: K115dH | AH1: K109dH | AI1: K114dH | AJ1: K080dH | AK1: K113dH | AL1: K074dH | AM1: K103dH | AN1: K117dH | AO1: K077dH | AP1: K063dH | AQ1: K101dH | AR1: K079dH | AS1: K105dH | AT1: K069dH | AU1: K070dH | AV1: K062dH | AW1: K073dH
A2: HILIC_neg_59_01351a1_44 | B2: 47769.273 | C2: 7268.8089 | D2: 5134.5687 | E2: 8717.1349 | F2: 7331.2291 | G2: 4002.5739 | H2: 42912.66 | I2: 6244.3354 | J2: 6912.6388 | K2: 36282.961 | L2: 64727.694 | M2: 18998.954 | N2: 14496.107 | O2: 8339.9937 | P2: 22414.308 | Q2: 43023.884 | R2: 15557.398 | S2: 55644.205 | T2: 20727.533 | U2: 17829.24 | V2: 22161.497 | W2: 8901.2172 | X2: 12467.947 | Y2: 9670.1392 | Z2: 5349.0186 | AA2: 7978.7753 | AB2: 157148.14 | AC2: 105061.82 | AD2: 42255.219 | AE2: 30653.668 | AF2: 37506.422 | AG2: 88376.068 | AH2: 84250.216 | AI2: 41402.27 | AJ2: 146499.96 | AK2: 17761.615 | AL2: 147307.23 | AM2: 28604.075 | AN2: 4904.4299 | AO2: 61270.245 | AP2: 5550.3372 | AQ2: 5694.5865 | AR2: 69737.213 | AS2: 5062.2929 | AT2: 6717.2556 | AU2: 2256.238 | AV2: 6471.5724 | AW2: 8178.1637
A3: HILIC_neg_88_04021a6_65 | B3: 131854.97 | C3: 118958.78 | D3: 69834.271 | E3: 59222.179 | F3: 67636.081 | G3: 62570.609 | H3: 63269.826 | I3: 92436.387 | J3: 106042.45 | K3: 87168.497 | L3: 83134.492 | M3: 67726.678 | N3: 100670.8 | O3: 99809.419 | P3: 110558.31 | Q3: 58403.514 | R3: 124112.74 | S3: 65599.877 | T3: 103013.29 | U3: 110839.73 | V3: 96931.954 | W3: 72849.84 | X3: 86405.233 | Y3: 73819.016 | Z3: 68969.735 | AA3: 74052.524 | AB3: 43316.946 | AC3: 12061.218 | AD3: 41701.174 | AE3: 35698.412 | AF3: 79352.375 | AG3: 50675.999 | AH3: 34026.492 | AI3: 68929.28 | AJ3: 15623.263 | AK3: 41079.658 | AL3: 8872.6486 | AM3: 17866.832 | AN3: 35394.558 | AO3: 15624.198 | AP3: 30484.77 | AQ3: 19414.543 | AR3: 24613.056 | AS3: 21316.217 | AT3: 70111.388 | AU3: 84390.503 | AV3: 54978.78 | AW3: 58642.43
A4: HILIC_neg_89_02456a1_407 | B4: 15811437 | C4: 10890780 | D4: 19419261 | E4: 21345605 | F4: 20773920 | G4: 23244824 | H4: 18974783 | I4: 11929495 | J4: 17579031 | K4: 19012279 | L4: 14524232 | M4: 18813368 | N4: 17339427 | O4: 14082689 | P4: 17875789 | Q4: 31299215 | R4: 15338935 | S4: 11485189 | T4: 9614879 | U4: 15455526 | V4: 11689027 | W4: 10466201 | X4: 14760806 | Y4: 15543950 | Z4: 79970.563 | AA4: 295647.5 | AB4: 29773820 | AC4: 14388091 | AD4: 9333521.4 | AE4: 2757219.4 | AF4: 12830171 | AG4: 46877343 | AH4: 24105267 | AI4: 13452885 | AJ4: 13766964 | AK4: 4236957.9 | AL4: 14194746 | AM4: 4839239.5 | AN4: 233216.48 | AO4: 906913.51 | AP4: 1653881.8 | AQ4: 429468.2 | AR4: 27396160 | AS4: 280583.15 | AT4: 82557.935 | AU4: 81682.791 | AV4: 1429533.1 | AW4: 204460.12
A5: HILIC_neg_102_05624a6_271 | B5: 203054.7 | C5: 212585.3 | D5: 173266.47 | E5: 155448.29 | F5: 213065.14 | G5: 187485.18 | H5: 149577.13 | I5: 178312.86 | J5: 233218.07 | K5: 182680.76 | L5: 187235.77 | M5: 191932.37 | N5: 263021.1 | O5: 228910.92 | P5: 215526.84 | Q5: 156199.99 | R5: 215690.16 | S5: 166551.02 | T5: 180615.81 | U5: 213353.54 | V5: 208958.35 | W5: 154075.02 | X5: 210833.01 | Y5: 211751.15 | Z5: 124152.37 | AA5: 91973.747 | AB5: 43525.607 | AC5: 27685.893 | AD5: 61280.464 | AE5: 56450.835 | AF5: 75493.533 | AG5: 62819.035 | AH5: 59774.65 | AI5: 92690.641 | AJ5: 41126.072 | AK5: 42287.041 | AL5: 21596.729 | AM5: 21043.552 | AN5: 54878.043 | AO5: 31482.735 | AP5: 61145.437 | AQ5: 37380.643 | AR5: 40097.79 | AS5: 34863.463 | AT5: 90948.354 | AU5: 137811.39 | AV5: 105288.13 | AW5: 70384.297
A6: HILIC_neg_102_96039a3_152 | B6: 28426.825 | C6: 31420.343 | D6: 22920.469 | E6: 28501.049 | F6: 30249.241 | G6: 35910.562 | H6: 32434.508 | I6: 22458.429 | J6: 44163.542 | K6: 32862.318 | L6: 36765.852 | M6: 30927.698 | N6: 32751.83 | O6: 38940.637 | P6: 43431.017 | Q6: 40852.412 | R6: 39220.594 | S6: 35872.813 | T6: 43691.616 | U6: 26181.666 | V6: 48365.227 | W6: 46042.596 | X6: 49504.178 | Y6: 45286.809 | Z6: 35652.266 | AA6: 30782.825 | AB6: 34614.717 | AC6: 15635.883 | AD6: 14319.646 | AE6: 18322.224 | AF6: 35175.231 | AG6: 26848.123 | AH6: 25593.629 | AI6: 41115.323 | AJ6: 14409.908 | AK6: 29867.232 | AL6: 12945.804 | AM6: 14597.959 | AN6: 21358.299 | AO6: 14799.297 | AP6: 5374.3677 | AQ6: 41546.049 | AR6: 16158.038 | AS6: 27460.852 | AT6: 36831.425 | AU6: 38588.093 | AV6: 23493.87 | AW6: 24805.014
A7: HILIC_neg_103_03951a0_992 | B7: 176302.62 | C7: 51664.519 | D7: 32064.681 | E7: 65630.107 | F7: 65260.098 | G7: 48746.129 | H7: 130251.05 | I7: 151812.83 | J7: 50718.035 | K7: 219295.94 | L7: 146717.2 | M7: 169162.1 | N7: 65191.811 | O7: 82936.23 | P7: 172638.9 | Q7: 465569.27 | R7: 170982.99 | S7: 130092.42 | T7: 139567.17 | U7: 110145.5 | V7: 106314.63 | W7: 82505.347 | X7: 80032.205 | Y7: 66147.717 | Z7: 17869.471 | AA7: 14643.621 | AB7: 359370.12 | AC7: 444339.26 | AD7: 370475.49 | AE7: 117701.37 | AF7: 521180.97 | AG7: 948458.25 | AH7: 794900.52 | AI7: 292225.55 | AJ7: 327017.35 | AK7: 436930.39 | AL7: 338560.58 | AM7: 138759.93 | AN7: 9668.9898 | AO7: 98954.528 | AP7: 24001.101 | AQ7: 22969.955 | AR7: 536286.38 | AS7: 19311.15 | AT7: 19078.405 | AU7: 13921.987 | AV7: 30444.166 | AW7: 25032.692
A8: HILIC_neg_104_03509a6_07 | B8: 59901.602 | C8: 66018.575 | D8: 45704.552 | E8: 29811.237 | F8: 51079.445 | G8: 63785.685 | H8: 45255.779 | I8: 59875.582 | J8: 96625.797 | K8: 58669.467 | L8: 45809.912 | M8: 69001.893 | N8: 60763.509 | O8: 53530.324 | P8: 76000.615 | Q8: 38289.435 | R8: 69252.093 | S8: 66450.522 | T8: 79218.219 | U8: 68729.044 | V8: 75798.594 | W8: 46975.871 | X8: 66181.868 | Y8: 48714.238 | Z8: 11564.271 | AA8: 15441.899 | AB8: 14475.116 | AC8: 10514.379 | AD8: 11303.41 | AE8: 15066.602 | AF8: 8808.851 | AG8: 14779.139 | AH8: 10938.053 | AI8: 14223.845 | AJ8: 15634.231 | AK8: 8295.7961 | AL8: 13540.679 | AM8: 10250.328 | AN8: 15372.809 | AO8: 10729.902 | AP8: 10796.597 | AQ8: 14120.833 | AR8: 13060.14 | AS8: 11132.491 | AT8: 13162.285 | AU8: 12947.116 | AV8: 11607.733 | AW8: 12563.225
A9: HILIC_neg_117_05537a0_773 | B9: 268599.68 | C9: 102430.41 | D9: 63793.959 | E9: 191492.91 | F9: 188810.03 | G9: 67859.312 | H9: 243409.2 | I9: 372312.35 | J9: 75940.999 | K9: 329522.08 | L9: 189657 | M9: 285541.95 | N9: 161016.17 | O9: 320055.84 | P9: 505878.56 | Q9: 729292.19 | R9: 309892.95 | S9: 160798.2 | T9: 207792.31 | U9: 129405.21 | V9: 185658.78 | W9: 176541.98 | X9: 99860.222 | Y9: 356285.68 | Z9: 11148.006 | AA9: 15522.668 | AB9: 382499.37 | AC9: 614651.8 | AD9: 442615.4 | AE9: 71721.9 | AF9: 894180.84 | AG9: 1049809.7 | AH9: 889341.25 | AI9: 721472.65 | AJ9: 322935.85 | AK9: 971504.61 | AL9: 287182.4 | AM9: 448714.48 | AN9: 19825.999 | AO9: 260985.3 | AP9: 21872.002 | AQ9: 19400.228 | AR9: 960690.03 | AS9: 18203.998 | AT9: 12023.733 | AU9: 20298.766 | AV9: 18807.401 | AW9: 28722.166
A10: HILIC_neg_118_05101a5_702 | B10: 135872.75 | C10: 135754.46 | D10: 72111.359 | E10: 82886.318 | F10: 140877.04 | G10: 149247.38 | H10: 98625.198 | I10: 100393.76 | J10: 180684.81 | K10: 99719.883 | L10: 144110.27 | M10: 141557.31 | N10: 102525.75 | O10: 156755.04 | P10: 175953.63 | Q10: 114192.41 | R10: 135196.36 | S10: 160388.13 | T10: 132904.46 | U10: 212109.89 | V10: 173272.33 | W10: 130532.39 | X10: 139205.51 | Y10: 103512.42 | Z10: 28481.103 | AA10: 29667.816 | AB10: 48099.475 | AC10: 39081.594 | AD10: 49528.754 | AE10: 43680.181 | AF10: 43918.529 | AG10: 76569.412 | AH10: 53086.914 | AI10: 53136.749 | AJ10: 47116.878 | AK10: 34058.114 | AL10: 42538.29 | AM10: 36267.175 | AN10: 33775.652 | AO10: 35098.914 | AP10: 25215.055 | AQ10: 25959.843 | AR10: 39617.682 | AS10: 25525.076 | AT10: 35985.499 | AU10: 31358.828 | AV10: 25533.387 | AW10: 36232.859
A11: HILIC_neg_124_00772a5_29 | B11: 936504.77 | C11: 963652.26 | D11: 673966.44 | E11: 693193.94 | F11: 858993.63 | G11: 896033.22 | H11: 742243.91 | I11: 817726.1 | J11: 984457.44 | K11: 820295.32 | L11: 1151049.8 | M11: 808126.34 | N11: 913609.53 | O11: 843201.06 | P11: 1081361.5 | Q11: 902512.43 | R11: 1062744.2 | S11: 1031276.4 | T11: 910864.18 | U11: 964068.33 | V11: 1022080.6 | W11: 859278.68 | X11: 977076.49 | Y11: 861985.8 | Z11: 7998.1132 | AA11: 18700.489 | AB11: 26724.305 | AC11: 55303.519 | AD11: 62011.409 | AE11: 103418.22 | AF11: 33212.557 | AG11: 85174.996 | AH11: 55107.572 | AI11: 10636.659 | AJ11: 170969.89 | AK11: 19169.459 | AL11: 321027.53 | AM11: 9020.494 | AN11: 7939.8738 | AO11: 26103.315 | AP11: 28058.148 | AQ11: 11000.966 | AR11: 480049.55 | AS11: 10372.396 | AT11: 11391.318 | AU11: 21777.135 | AV11: 68626.467 | AW11: 13447.312
A12: HILIC_neg_128_95963a3_171 | B12: 695788.99 | C12: 690315.58 | D12: 575656.3 | E12: 617291.7 | F12: 683360.84 | G12: 761536.76 | H12: 661656.48 | I12: 595652.44 | J12: 836629.49 | K12: 706830.43 | L12: 737237.85 | M12: 691261.22 | N12: 732610.29 | O12: 710688.91 | P12: 757605.93 | Q12: 714164.66 | R12: 705484.03 | S12: 615350.93 | T12: 706124.34 | U12: 775378.92 | V12: 729393.79 | W12: 687404.22 | X12: 721770.24 | Y12: 700631.63 | Z12: 457730.48 | AA12: 387532.39 | AB12: 385059.52 | AC12: 290729.37 | AD12: 313892.35 | AE12: 304354.41 | AF12: 407781.83 | AG12: 352645.02 | AH12: 458424.44 | AI12: 508361.76 | AJ12: 251491.97 | AK12: 319924.76 | AL12: 237665.34 | AM12: 275285.56 | AN12: 355794.29 | AO12: 259239.53 | AP12: 282987.79 | AQ12: 499564.01 | AR12: 268989.56 | AS12: 356293.01 | AT12: 440876.74 | AU12: 469438.84 | AV12: 374303.83 | AW12: 445589.15
A13: HILIC_neg_130_06177a5_514 | B13: 297737.78 | C13: 237604.6 | D13: 252778.22 | E13: 198785 | F13: 314369 | G13: 306916.47 | H13: 311211.33 | I13: 286041.64 | J13: 316235.21 | K13: 319098.24 | L13: 466220.24 | M13: 319764.62 | N13: 363837.87 | O13: 335294.42 | P13: 330651.66 | Q13: 335338.62 | R13: 332815.71 | S13: 363543.88 | T13: 296638.12 | U13: 395296.51 | V13: 373842.59 | W13: 258502.98 | X13: 331999.85 | Y13: 370896.05 | Z13: 786.73835 | AA13: 9415.6177 | AB13: 4843.4732 | AC13: 13373.761 | AD13: 7094.4873 | AE13: 24535.263 | AF13: 4991.3711 | AG13: 15077.892 | AH13: 4221.6087 | AI13: 2627.4495 | AJ13: 66298.699 | AK13: 7908.3636 | AL13: 91622.106 | AM13: 4983.3015 | AN13: 4725.3414 | AO13: 30102.331 | AP13: 19652.465 | AQ13: 7946.4567 | AR13: 32035.517 | AS13: 4087.4418 | AT13: 4125.6601 | AU13: 9962.5551 | AV13: 41550.636 | AW13: 8038.885
... A1838: RP_pos_1568_1637a12_33 | B1838: 2998332.2 | C1838: 2037670.9 | D1838: 2597383.6 | E1838: 1921758.6 | F1838: 2031233.9 | G1838: 2734223.7 | H1838: 1619300.2 | I1838: 1922488.8 | J1838: 3196713.4 | K1838: 1818965.3 | L1838: 1852508.9 | M1838: 2289687.1 | N1838: 2492183.2 | O1838: 1711867.2 | P1838: 3590595.8 | Q1838: 1509473.1 | R1838: 2826071.1 | S1838: 1566739.8 | T1838: 1720296.6 | U1838: 1987648.9 | V1838: 2620041.8 | W1838: 1472616 | X1838: 2735735.8 | Y1838: 1669321.7 | Z1838: 46835.264 | AA1838: 34444.208 | AB1838: 4186.9982 | AC1838: 3283.5712 | AD1838: 1979.3391 | AE1838: 23623.086 | AF1838: 547.45631 | AG1838: 11793.793 | AH1838: 1193.5001 | AI1838: 0 | AJ1838: 26376.77 | AK1838: 1842.7535 | AL1838: 48809.099 | AM1838: 2606.9953 | AN1838: 6484.518 | AO1838: 2175.8376 | AP1838: 27060.346 | AQ1838: 6780.253 | AR1838: 4841.3366 | AS1838: 3628.2213 | AT1838: 0 | AU1838: 22827.51 | AV1838: 40673.262 | AW1838: 10997.452

Sheet Sample metadata
A1: SAMPLE_ID | B1: 3D'omics | C1: SAMPLE_TYPE | D1: Sample type | E1: PEN | F1: Diet | G1: Group | H1: TRIAL | I1: HILIC_neg_Datafile | J1: HILIC_pos_Datafile | K1: RP_neg_Datafile | L1: RP_pos_Datafile
A2: K107dI | B2: K107 | C2: I | D2: Tissue | E2: 12 | F2: 3 | G2: HEBV | H2: 7-2-2 | I2: 240326ST_3DO_Swine Conventional_HILIC_neg_067 | J2: 240323ST_3DO_Swine Conventional_HILIC_pos_082 | K2: 240319ST_3DO_Swine Conventional_RP_neg_067 | L2: 240315ST_3DO_Swine Conventional_RP_pos_082
A3: K069dI | B3: K069 | C3: I | D3: Tissue | E3: 2 | F3: 1 | G3: HEBV | H3: 7-2-2 | I3: 240326ST_3DO_Swine Conventional_HILIC_neg_068 | J3: 240323ST_3DO_Swine Conventional_HILIC_pos_083 | K3: 240319ST_3DO_Swine Conventional_RP_neg_068 | L3: 240315ST_3DO_Swine Conventional_RP_pos_083
A4: K105dI | B4: K105 | C4: I | D4: Tissue | E4: 11 | F4: 3 | G4: HEBV | H4: 7-2-2 | I4: 240326ST_3DO_Swine Conventional_HILIC_neg_069 | J4: 240323ST_3DO_Swine Conventional_HILIC_pos_084 | K4: 240319ST_3DO_Swine Conventional_RP_neg_069 | L4: 240315ST_3DO_Swine Conventional_RP_pos_084
A5: K064dI | B5: K064 | C5: I | D5: Tissue | E5: 1 | F5: 1 | G5: HEBV | H5: 7-2-2 | I5: 240326ST_3DO_Swine Conventional_HILIC_neg_070 | J5: 240323ST_3DO_Swine Conventional_HILIC_pos_085 | K5: 240319ST_3DO_Swine Conventional_RP_neg_070 | L5: 240315ST_3DO_Swine Conventional_RP_pos_085
A6: K063dI | B6: K063 | C6: I | D6: Tissue | E6: 1 | F6: 1 | G6: HEBV | H6: 7-2-2 | I6: 240326ST_3DO_Swine Conventional_HILIC_neg_071 | J6: 240323ST_3DO_Swine Conventional_HILIC_pos_086 | K6: 240319ST_3DO_Swine Conventional_RP_neg_071 | L6: 240315ST_3DO_Swine Conventional_RP_pos_086
A7: K101dI | B7: K101 | C7: I | D7: Tissue | E7: 11 | F7: 3 | G7: HEBV | H7: 7-2-2 | I7: 240326ST_3DO_Swine Conventional_HILIC_neg_072 | J7: 240323ST_3DO_Swine Conventional_HILIC_pos_087 | K7: 240319ST_3DO_Swine Conventional_RP_neg_072 | L7: 240315ST_3DO_Swine Conventional_RP_pos_087
A8: K106dI | B8: K106 | C8: I | D8: Tissue | E8: 12 | F8: 3 | G8: HEBV | H8: 7-2-2 | I8: 240326ST_3DO_Swine Conventional_HILIC_neg_074 | J8: 240323ST_3DO_Swine Conventional_HILIC_pos_089 | K8: 240319ST_3DO_Swine Conventional_RP_neg_074 | L8: 240315ST_3DO_Swine Conventional_RP_pos_089
A9: K113dI | B9: K113 | C9: I | D9: Tissue | E9: 13 | F9: 3 | G9: LEBV | H9: 7-2-2 | I9: 240326ST_3DO_Swine Conventional_HILIC_neg_075 | J9: 240323ST_3DO_Swine Conventional_HILIC_pos_090 | K9: 240319ST_3DO_Swine Conventional_RP_neg_075 | L9: 240315ST_3DO_Swine Conventional_RP_pos_090
A10: K062dI | B10: K062 | C10: I | D10: Tissue | E10: 1 | F10: 1 | G10: HEBV | H10: 7-2-2 | I10: 240326ST_3DO_Swine Conventional_HILIC_neg_076 | J10: 240323ST_3DO_Swine Conventional_HILIC_pos_091 | K10: 240319ST_3DO_Swine Conventional_RP_neg_076 | L10: 240315ST_3DO_Swine Conventional_RP_pos_091
A11: K109dI | B11: K109 | C11: I | D11: Tissue | E11: 12 | F11: 3 | G11: HEBV | H11: 7-2-2 | I11: 240326ST_3DO_Swine Conventional_HILIC_neg_077 | J11: 240323ST_3DO_Swine Conventional_HILIC_pos_092 | K11: 240319ST_3DO_Swine Conventional_RP_neg_077 | L11: 240315ST_3DO_Swine Conventional_RP_pos_092
A12: K074dI | B12: K074 | C12: I | D12: Tissue | E12: 3 | F12: 1 | G12: LEBV | H12: 7-2-2 | I12: 240326ST_3DO_Swine Conventional_HILIC_neg_078 | J12: 240323ST_3DO_Swine Conventional_HILIC_pos_093 | K12: 240319ST_3DO_Swine Conventional_RP_neg_078 | L12: 240315ST_3DO_Swine Conventional_RP_pos_093
A13: K114dI | B13: K114 | C13: I | D13: Tissue | E13: 13 | F13: 3 | G13: LEBV | H13: 7-2-2 | I13: 240326ST_3DO_Swine Conventional_HILIC_neg_079 | J13: 240323ST_3DO_Swine Conventional_HILIC_pos_094 | K13: 240319ST_3DO_Swine Conventional_RP_neg_079 | L13: 240315ST_3DO_Swine Conventional_RP_pos_094
... A49: K073dH | B49: K073 | C49: H | D49: Digesta | E49: 3 | F49: 1 | G49: LEBV | H49: 7-2-2 | I49: 240326ST_3DO_Swine Conventional_HILIC_neg_224 | J49: 240323ST_3DO_Swine Conventional_HILIC_pos_239 | K49: 240319ST_3DO_Swine Conventional_RP_neg_224 | L49: 240315ST_3DO_Swine Conventional_RP_pos_239

Sheet Annotations
A1: Feature_ID | B1: Split | C1: Average_Rt_min_ | D1: Average_Mz | E1: Curated_ID | F1: ID Level | G1: Class | H1: Formula | I1: KEGG ID | J1: Database ID
A2: HILIC_pos_282_1199a4_375 | B2: HILIC_pos | C2: 4.375 | D2: 282.1199 | E2: 1-Methyladenosine | F2: 1 | G2: Nucleosides, nucleotides, and analogues | H2: C11H15N5O4 | I2: C02494 | J2: HMDB0003331
A3: HILIC_pos_204_12305a3_15 | B3: HILIC_pos | C3: 3.15 | D3: 204.12305 | E3: Acetylcarnitine | F3: 1 | G3: Acylcarnitines | H3: C9H17NO4 | I3: C02571 | J3: HMDB0000201
A4: RP_pos_162_09132a4_953 | B4: RP_pos | C4: 4.953 | D4: 162.09132 | E4: Tryptophol | F4: 1 | G4: Indoles and derivatives | H4: C10H11NO | I4: C00955 | J4: HMDB0003447
A5: RP_pos_161_10786a2_57 | B5: RP_pos | C5: 2.57 | D5: 161.10786 | E5: Tryptamine | F5: 1 | G5: Indoles and derivatives | H5: C10H12N2 | I5: C00398 | J5: HMDB0000303
A6: RP_pos_177_10252a1_429 | B6: RP_pos | C6: 1.429 | D6: 177.10252 | E6: Serotonin | F6: 1 | G6: Indoles and derivatives | H6: C10H12N2O | I6: C00780 | J6: HMDB0000259
A7: RP_pos_209_09212a1_716 | B7: RP_pos | C7: 1.716 | D7: 209.09212 | E7: Kynurenine | F7: 1 | G7: Amino acids and derivatives | H7: C10H12N2O3 | I7: C00328 | J7: HMDB0000684
A8: RP_pos_268_10461a1_422 | B8: RP_pos | C8: 1.422 | D8: 268.10461 | E8: Adenosine | F8: 1 | G8: Nucleosides, nucleotides, and analogues | H8: C10H13N5O4 | I8: C00212 | J8: HMDB0000050
A9: HILIC_pos_284_09863a4_18 | B9: HILIC_pos | C9: 4.18 | D9: 284.09863 | E9: Guanosine | F9: 1 | G9: Nucleosides, nucleotides, and analogues | H9: C10H13N5O5 | I9: C00387 | J9: HMDB0000133
A10: HILIC_pos_348_07047a7_608 | B10: HILIC_pos | C10: 7.608 | D10: 348.07047 | E10: Adenylic acid (AMP) | F10: 1 | G10: Nucleosides, nucleotides, and analogues | H10: C10H14N5O7P | I10: C00020 | J10: HMDB0000045
A11: RP_neg_201_1131a6_45 | B11: RP_neg | C11: 6.45 | D11: 201.1131 | E11: Sebacic acid (aka decanedioic acid) | F11: 1 | G11: Fatty acyls | H11: C10H18O4 | I11: C08277 | J11: HMDB0000792
A12: RP_pos_218_13914a1_324 | B12: RP_pos | C12: 1.324 | D12: 218.13914 | E12: CAR 3:0 | F12: 1 | G12: Acylcarnitine | H12: C10H19NO4 | I12: C03017 | J12: HMDB0000824
A13: RP_pos_190_0498a3_236 | B13: RP_pos | C13: 3.236 | D13: 190.0498 | E13: Kynurenic acid | F13: 1 | G13: Quinolines and derivatives | H13: C10H7NO3 | I13: C01717 | J13: HMDB0000715
... A122: RP_neg_407_28064a7_729 | B122: RP_neg | C122: 7.729 | D122: 407.28064 | E122: Ursocholic acid | F122: 1 | G122: Bile acids | H122: HMDB0000917 | I122: C17644 | J122: HMDB0000917
A123: RP_pos_196_09697a2_095 | B123: RP_pos | C123: 2.095 | D123: 196.09697 | E123: Methyltyrosinate | F123: 2 | G123: Amino acids and derivatives | H123: C10H13NO3 | I123: NA
A124: HILIC_pos_229_11823a6_037 | B124: HILIC_pos | C124: 6.037 | D124: 229.11823 | E124: Prolylhydroxyproline | F124: 2 | G124: Amino acids and derivatives | H124: C10H16N2O4 | I124: NA | J124: HMDB0006695
A125: RP_neg_190_05119a3_946 | B125: RP_neg | C125: 3.946 | D125: 190.05119 | E125: Oxindole acetic acid | F125: 2 | G125: Oxindoles | H125: C10H9NO3 | I125: NA | J125: 3080590
A126: RP_pos_261_14429a3_098 | B126: RP_pos | C126: 3.098 | D126: 261.14429 | E126: Glutamylleucine | F126: 2 | G126: Amino acids and derivatives | H126: C11H20N2O5 | I126: NA | J126: HMDB0011171
A127: RP_pos_231_17026a2_873 | B127: RP_pos | C127: 2.873 | D127: 231.17026 | E127: Valyl leucine | F127: 2 | G127: Amino acids and derivatives | H127: C11H22N2O3 | I127: NA | J127: HMDB0029131
A128: RP_neg_229_14464a7_566 | B128: RP_neg | C128: 7.566 | D128: 229.14464 | E128: Dodecanedioic acid | F128: 2 | G128: Fatty acyls | H128: C12H22O4 | I128: C02678 | J128: HMDB0000623
A129: RP_pos_245_18558a3_236 | B129: RP_pos | C129: 3.236 | D129: 245.18558 | E129: Leucyl leucine | F129: 2 | G129: Amino acids and derivatives | H129: C12H24N2O3 | I129: C11332 | J129: HMDB0254039
A130: RP_pos_384_11499a2_426 | B130: RP_pos | C130: 2.426 | D130: 384.11499 | E130: Succinyladenosine | F130: 2 | G130: Purine nucleosides | H130: C14H17N5O8 | I130: NA | J130: HMDB0000912
A131: RP_neg_326_08826a3_049 | B131: RP_neg | C131: 3.049 | D131: 326.08826 | E131: Acetaminophen-glucuronide | F131: 2 | G131: Glycosides | H131: C14H17NO8 | I131: NA | J131: HMDB0010316
A132: RP_pos_279_13385a2_27 | B132: RP_pos | C132: 2.27 | D132: 279.13385 | E132: Tyrosyl proline | F132: 2 | G132: Amino acids and derivatives | H132: C14H18N2O4 | I132: NA | J132: HMDB0029113
A133: RP_pos_310_16568a3_005 | B133: RP_pos | C133: 3.005 | D133: 310.16568 | E133: Sinapine | F133: 2 | G133: Alkaloid | H133: C16H24NO5 | I133: C00933 | J133: HMDB0029379
A134: RP_neg_271_22803a9_611 | B134: RP_neg | C134: 9.611 | D134: 271.22803 | E134: Hydroxyhexadecanoic acid | F134: 2 | G134: Long-chain fatty acids | H134: C16H32O3 | I134: NA | J134: Ex: HMDB0031057
A135: RP_pos_283_26389a9_946 | B135: RP_pos | C135: 9.946 | D135: 283.26389 | E135: Oleic acid | F135: 2 | G135: Long-chain fatty acids | H135: C18H34O2 | I135: C00712 | J135: HMDB0000207
A136: RP_pos_300_29037a8_864 | B136: RP_pos | C136: 8.864 | D136: 300.29037 | E136: Sphingosine | F136: 2 | G136: Organonitrogen compounds | H136: C18H37NO2 | I136: C00319 | J136: HMDB0000252
A137: RP_pos_316_28494a8_545 | B137: RP_pos | C137: 8.545 | D137: 316.28494 | E137: Dehydrophytosphingosine | F137: 2 | G137: Organonitrogen compounds | H137: C18H37NO3 | I137: NA | J137: HMDB0038057
... A149: HILIC_pos_595_3504a1_164 | B149: HILIC_pos | C149: 1.164 | D149: 595.3504 | E149: Stercobilin | F149: 2 | G149: Bilirubins | H149: C33H46N4O6 | I149: C05793 | J149: HMDB0240259
A150: RP_neg_714_50787a12_177 | B150: RP_neg | C150: 12.177 | D150: 714.50787 | E150: PE 18:2/16:0 | F150: 2 | G150: Glycerophospholipids | H150: C39H74NO8P | I150: NA
A151: RP_pos_756_55469a11_89 | B151: RP_pos | C151: 11.89 | D151: 756.55469 | E151: PC(16:1/18:2) | F151: 2 | G151: Glycerophospholipids | H151: C42H78NO8P | I151: C00157 | J151: LMGP01010690
A152: RP_pos_810_60114a12_552 | B152: RP_pos | C152: 12.552 | D152: 810.60114 | E152: PC(18:1/20:3) | F152: 2 | G152: Glycerophospholipids | H152: C46H84NO8P | I152: C00157 | J152: LMGP01010904
A153: HILIC_pos_104_07069a5_307 | B153: HILIC_pos | C153: 5.307 | D153: 104.07069 | E153: Dimethylglycine | F153: 2 | G153: Amino acids and derivatives | H153: C4H9NO2 | I153: C01026 | J153: HMDB0000092
A154: RP_neg_117_05578a2_691 | B154: RP_neg | C154: 2.691 | D154: 117.05578 | E154: 3-Hydroisovaleric acid | F154: 2 | G154: Fatty acyls | H154: C5H10O3 | I154: C20827 | J154: HMDB0000754
A155: HILIC_neg_117_05537a0_773 | B155: HILIC_neg | C155: 0.773 | D155: 117.05537 | E155: 3-Hydroxyvaleric acid | F155: 2 | G155: Fatty acyls | H155: C5H10O3 | I155: NA | J155: HMDB0000531
A156: HILIC_pos_146_09247a3_906 | B156: HILIC_pos | C156: 3.906 | D156: 146.09247 | E156: 4-Guanidinobutanoic acid | F156: 2 | G156: Amino acids and derivatives | H156: C5H11N3O2 | I156: C01035 | J156: HMDB0003464
A157: HILIC_pos_166_05328a5_993 | B157: HILIC_pos | C157: 5.993 | D157: 166.05328 | E157: Methioninesulfoxide | F157: 2 | G157: Amino acids and derivatives | H157: C5H11NO3S | I157: C02989 | J157: HMDB0002005
A158: HILIC_pos_145_10831a3_283 | B158: HILIC_pos | C158: 3.283 | D158: 145.10831 | E158: 4-guanidinobutanamide | F158: 2 | G158: Amino acids and derivatives | H158: C5H12N4O | I158: C03078 | J158: C03078
A159: HILIC_pos_104_10734a1_583 | B159: HILIC_pos | C159: 1.583 | D159: 104.10734 | E159: Choline | F159: 2 | G159: Organonitrogen compounds | H159: C5H14NO | I159: C00114 | J159: HMDB0000097
...

Sheet Reordered Abundances
A1: Feature_ID | B1: Curated_ID | C1: K107dI | D1: K069dI | E1: K105dI | F1: K064dI | G1: K063dI | H1: K101dI | I1: K106dI | J1: K113dI | K1: K062dI | L1: K109dI | M1: K074dI | N1: K114dI | O1: K103dI | P1: K070dI | Q1: K079dI | R1: K115dI | S1: K120dI | T1: K080dI | U1: K116dI | V1: K067dI | W1: K077dI | X1: K073dI | Y1: K071dI | Z1: K117dI | AA1: K064dH | AB1: K071dH | AC1: K106dH | AD1: K107dH | AE1: K116dH | AF1: K067dH | AG1: K120dH | AH1: K115dH | AI1: K109dH | AJ1: K114dH | AK1: K080dH | AL1: K113dH | AM1: K074dH | AN1: K103dH | AO1: K117dH | AP1: K077dH | AQ1: K063dH | AR1: K101dH | AS1: K079dH | AT1: K105dH | AU1: K069dH | AV1: K070dH | AW1: K062dH | AX1: K073dH
A2: HILIC_pos_282_1199a4_375 | B2: 1-Methyladenosine | C2: 186738.16 | D2: 179653.56 | E2: 162625.25 | F2: 142029.39 | G2: 179985.13 | H2: 165023.16 | I2: 129596.35 | J2: 148272.36 | K2: 260802.98 | L2: 145894.89 | M2: 164340.4 | N2: 177843.96 | O2: 165524.75 | P2: 159498.15 | Q2: 154920.43 | R2: 123986.81 | S2: 166318.18 | T2: 182724.06 | U2: 120166.49 | V2: 163377.93 | W2: 154838.71 | X2: 142023.83 | Y2: 145891.54 | Z2: 164553.96 | AA2: 13595.475 | AB2: 26113.645 | AC2: 8098.3877 | AD2: 37938.995 | AE2: 17036.348 | AF2: 69932.173 | AG2: 9853.309 | AH2: 44775.001 | AI2: 11271.92 | AJ2: 12433.199 | AK2: 109855.53 | AL2: 26345.647 | AM2: 181268.99 | AN2: 23759.252 | AO2: 31748.388 | AP2: 92008.378 | AQ2: 75231.155 | AR2: 39734.645 | AS2: 75288.773 | AT2: 23411.899 | AU2: 15167.18 | AV2: 41458.557 | AW2: 94368.308 | AX2: 29961.761
A3: HILIC_pos_204_12305a3_15 | B3: Acetylcarnitine | C3: 6792216.9 | D3: 7622000.9 | E3: 6061464.4 | F3: 18977354 | G3: 8780696.2 | H3: 8915433.4 | I3: 8086094.4 | J3: 8644530.1 | K3: 9180644.6 | L3: 7012017.4 | M3: 13239169 | N3: 10736941 | O3: 8929376.7 | P3: 8362891.2 | Q3: 18277785 | R3: 12496827 | S3: 14157172 | T3: 7769395.4 | U3: 10346483 | V3: 11437962 | W3: 13515925 | X3: 11486921 | Y3: 7152144.5 | Z3: 8569794.3 | AA3: 19593.01 | AB3: 259419.79 | AC3: 241170.6 | AD3: 845362.08 | AE3: 281598.89 | AF3: 524655.66 | AG3: 357539.12 | AH3: 698109.27 | AI3: 366901.88 | AJ3: 70834.786 | AK3: 2130690.1 | AL3: 490688.06 | AM3: 4315725.5 | AN3: 285238.16 | AO3: 138848.89 | AP3: 1105232.2 | AQ3: 773021.08 | AR3: 257983.23 | AS3: 1350993 | AT3: 77970.56 | AU3: 48907.605 | AV3: 170602.16 | AW3: 1015199.5 | AX3: 199411.87
A4: RP_pos_162_09132a4_953 | B4: Tryptophol | C4: 290608.21 | D4: 221598.18 | E4: 182150.88 | F4: 23235.748 | G4: 265440.76 | H4: 303343.67 | I4: 77971.539 | J4: 277992.92 | K4: 314891.32 | L4: 98669.87 | M4: 36458.571 | N4: 225713.64 | O4: 100684.58 | P4: 148462.49 | Q4: 45652.287 | R4: 212681.84 | S4: 105385.01 | T4: 61227.234 | U4: 188483.38 | V4: 85428.012 | W4: 84357.875 | X4: 117610.97 | Y4: 56457.164 | Z4: 246072.6 | AA4: 33817.327 | AB4: 59875.134 | AC4: 78325.272 | AD4: 360088.05 | AE4: 249303.44 | AF4: 86507.53 | AG4: 102712.81 | AH4: 252779.84 | AI4: 138838.08 | AJ4: 216369.88 | AK4: 42102.988 | AL4: 334459.66 | AM4: 15011.897 | AN4: 115315.12 | AO4: 367368.47 | AP4: 31058.826 | AQ4: 276145.78 | AR4: 312269.27 | AS4: 26059.268 | AT4: 151941.69 | AU4: 172550.77 | AV4: 210034.29 | AW4: 229550.39 | AX4: 111774.9
A5: RP_pos_161_10786a2_57 | B5: Tryptamine | C5: 2411510.2 | D5: 1003944.8 | E5: 1329377.9 | F5: 716414.4 | G5: 223704.18 | H5: 203901.19 | I5: 1879276.1 | J5: 3335362.7 | K5: 151467.56 | L5: 2216337.4 | M5: 335602.06 | N5: 1901943.4 | O5: 1413267.3 | P5: 203049.3 | Q5: 1901739.4 | R5: 2864242.9 | S5: 3249120.9 | T5: 1593802.1 | U5: 4037127.8 | V5: 1020315.8 | W5: 2379701.5 | X5: 1951299.9 | Y5: 1626709.8 | Z5: 1760759.3 | AA5: 2125139.1 | AB5: 5159767.3 | AC5: 5644588.3 | AD5: 8598984.1 | AE5: 10087573 | AF5: 3939109.5 | AG5: 8927692.6 | AH5: 6268028.4 | AI5: 7362760.5 | AJ5: 5084629.4 | AK5: 5888872 | AL5: 9233738.7 | AM5: 1259747.9 | AN5: 6120458.4 | AO5: 4590165 | AP5: 8317938.7 | AQ5: 721648.5 | AR5: 683882.66 | AS5: 5947138.7 | AT5: 3201088.9 | AU5: 2686773.5 | AV5: 777739.23 | AW5: 612531.5 | AX5: 4109472.8
A6: RP_pos_177_10252a1_429 | B6: Serotonin | C6: 1152685 | D6: 1473044.8 | E6: 771885.31 | F6: 870405.48 | G6: 955791.37 | H6: 1171286.4 | I6: 1360225 | J6: 821579.16 | K6: 1359191.3 | L6: 1004240.3 | M6: 565193.25 | N6: 2015705.4 | O6: 969133.42 | P6: 1096399.6 | Q6: 960648.8 | R6: 774173.28 | S6: 1001525.7 | T6: 936344.64 | U6: 753573.78 | V6: 708067.5 | W6: 835607.04 | X6: 1133665.1 | Y6: 820651.64 | Z6: 643430.37 | AA6: 38596.621 | AB6: 64402.735 | AC6: 55400.353 | AD6: 51805.178 | AE6: 38409.031 | AF6: 28088.852 | AG6: 57696.364 | AH6: 34446.124 | AI6: 45111.019 | AJ6: 52299.762 | AK6: 85576.773 | AL6: 57646.62 | AM6: 121270.54 | AN6: 43210.691 | AO6: 47391.477 | AP6: 39814.636 | AQ6: 16143.037 | AR6: 16522.703 | AS6: 47314.81 | AT6: 55437.283 | AU6: 17879.399 | AV6: 12958.32 | AW6: 31299.163 | AX6: 43654.92
A7: RP_pos_209_09212a1_716 | B7: Kynurenine | C7: 139676.52 | D7: 81647.082 | E7: 79155.918 | F7: 97113.598 | G7: 109970.71 | H7: 111687.48 | I7: 51794.374 | J7: 97110.428 | K7: 119474.91 | L7: 97158.203 | M7: 69045.552 | N7: 92169.595 | O7: 137231.86 | P7: 64563.546 | Q7: 163927.75 | R7: 77171.152 | S7: 63294.875 | T7: 73386.712 | U7: 60200.871 | V7: 210422.91 | W7: 127980.38 | X7: 65226.468 | Y7: 121440.41 | Z7: 87771.133 | AA7: 24210.047 | AB7: 23477.675 | AC7: 47816.131 | AD7: 36195.183 | AE7: 46662.439 | AF7: 41885.851 | AG7: 28940.513 | AH7: 62086.928 | AI7: 64770.152 | AJ7: 32839.564 | AK7: 63433.427 | AL7: 34321.604 | AM7: 38635.85 | AN7: 40504.855 | AO7: 23057.458 | AP7: 63518.451 | AQ7: 22135.272 | AR7: 23901.145 | AS7: 55686.955 | AT7: 22028.27 | AU7: 22858.49 | AV7: 20157.91 | AW7: 24488.911 | AX7: 32347.177
A8: RP_pos_268_10461a1_422 | B8: Adenosine | C8: 4177193.9 | D8: 6629607 | E8: 6471013.9 | F8: 7261421 | G8: 7938597.8 | H8: 5388137.1 | I8: 6289221.2 | J8: 5553463.9 | K8: 10766716 | L8: 7022420.6 | M8: 4714644.5 | N8: 9495063.8 | O8: 7409918 | P8: 8401427.5 | Q8: 4835156.2 | R8: 5224853.5 | S8: 5960506 | T8: 5977564.7 | U8: 4946237.6 | V8: 6288017.6 | W8: 7767278.9 | X8: 5638208.9 | Y8: 11032892 | Z8: 7638455.4 | AA8: 1977011.3 | AB8: 1116329.8 | AC8: 763398.77 | AD8: 900964.61 | AE8: 714947.37 | AF8: 1282672.8 | AG8: 1001515.3 | AH8: 957041.53 | AI8: 580502.97 | AJ8: 1635207.5 | AK8: 2891474.1 | AL8: 1442038.3 | AM8: 572742.46 | AN8: 1402295.7 | AO8: 2353667 | AP8: 1958984.4 | AQ8: 1348782.7 | AR8: 2670188.6 | AS8: 576716.64 | AT8: 1708494.8 | AU8: 2164669.2 | AV8: 2198776.5 | AW8: 1431091.2 | AX8: 1209043.7
A9: HILIC_pos_284_09863a4_18 | B9: Guanosine | C9: 112203.88 | D9: 102525.72 | E9: 137254.37 | F9: 131765.98 | G9: 107592.69 | H9: 100244.28 | I9: 91771.011 | J9: 102786.78 | K9: 144537.88 | L9: 120459.44 | M9: 119087.1 | N9: 120716.16 | O9: 122709.08 | P9: 127305.92 | Q9: 136025.05 | R9: 114374.18 | S9: 100210.22 | T9: 103328.29 | U9: 122178.54 | V9: 104937.41 | W9: 108834.14 | X9: 115934.29 | Y9: 117552.52 | Z9: 140105.96 | AA9: 8557.1088 | AB9: 7203.1639 | AC9: 6636.9065 | AD9: 9843.9461 | AE9: 6137.5872 | AF9: 15399.461 | AG9: 6483.4212 | AH9: 14907.159 | AI9: 4064.1488 | AJ9: 9107.977 | AK9: 45471.763 | AL9: 8275.1589 | AM9: 87538.158 | AN9: 8458.23 | AO9: 14167.732 | AP9: 21707.181 | AQ9: 12677.362 | AR9: 31803.421 | AS9: 10134.759 | AT9: 11743.021 | AU9: 7648.2955 | AV9: 16915.154 | AW9: 16210.782 | AX9: 9314.1141
A10: HILIC_pos_348_07047a7_608 | B10: Adenylic acid (AMP) | C10: 26335.405 | D10: 42233.416 | E10: 22449.394 | F10: 26375.448 | G10: 31162.634 | H10: 27462.424 | I10: 30207.343 | J10: 18513.49 | K10: 44578.694 | L10: 36212.624 | M10: 55407.954 | N10: 29056.561 | O10: 35332.642 | P10: 34751.93 | Q10: 53511.286 | R10: 33866.254 | S10: 33799.228 | T10: 45073.207 | U10: 28631.061 | V10: 37231.424 | W10: 44686.511 | X10: 36999.716 | Y10: 38031.02 | Z10: 44338.878 | AA10: 7410.259 | AB10: 3829.0319 | AC10: 3380.6441 | AD10: 315.51237 | AE10: 213.05374 | AF10: 4724.8814 | AG10: 2512.5037 | AH10: 5933.4587 | AI10: 2352.1635 | AJ10: 3224.7773 | AK10: 11414.816 | AL10: 1757.7301 | AM10: 8462.0374 | AN10: 401.88295 | AO10: 4540.6853 | AP10: 5525.829 | AQ10: 3154.9405 | AR10: 2032.2979 | AS10: 3262.3202 | AT10: 2761.8728 | AU10: 7018.1991 | AV10: 4065.5426 | AW10: 5157.8775 | AX10: 5023.7712
A11: RP_neg_201_1131a6_45 | B11: Sebacic acid (aka decanedioic acid) | C11: 164502.26 | D11: 211616.45 | E11: 335504.08 | F11: 299896.2 | G11: 197648.6 | H11: 263681.53 | I11: 220872.79 | J11: 208176.61 | K11: 223510.71 | L11: 144876.2 | M11: 122762.74 | N11: 212374.71 | O11: 183961.5 | P11: 198922.14 | Q11: 158247.06 | R11: 222895.95 | S11: 178476.12 | T11: 143303.45 | U11: 164611.54 | V11: 156608.96 | W11: 163491.84 | X11: 228918.7 | Y11: 217515.22 | Z11: 241978.94 | AA11: 700450.21 | AB11: 591380.21 | AC11: 488770.36 | AD11: 410087.86 | AE11: 352676.98 | AF11: 318394.57 | AG11: 386029.92 | AH11: 407359.28 | AI11: 317381.38 | AJ11: 611570.06 | AK11: 233058.12 | AL11: 543300.68 | AM11: 157979.34 | AN11: 376710.58 | AO11: 701387.78 | AP11: 267119.86 | AQ11: 439425.9 | AR11: 764149.81 | AS11: 199120.19 | AT11: 858866.3 | AU11: 522807.31 | AV11: 527657.44 | AW11: 420639.87 | AX11: 483419.46
A12: RP_pos_218_13914a1_324 | B12: CAR 3:0 | C12: 5791161.9 | D12: 2863252.6 | E12: 4029656.1 | F12: 2885616.3 | G12: 4797676.7 | H12: 3758392 | I12: 4761073.8 | J12: 5714420.4 | K12: 4049683.7 | L12: 4159622.7 | M12: 10849886 | N12: 5616629.6 | O12: 7174432.6 | P12: 6331450.1 | Q12: 6068472.7 | R12: 4050230.7 | S12: 8094872.2 | T12: 5114307.1 | U12: 3538848.6 | V12: 5881463.1 | W12: 10425618 | X12: 2743613.5 | Y12: 5183141.8 | Z12: 6559053.5 | AA12: 14412.797 | AB12: 58027.465 | AC12: 37177.274 | AD12: 154680.93 | AE12: 41309.106 | AF12: 72341.82 | AG12: 69925.268 | AH12: 119431.84 | AI12: 58892.068 | AJ12: 55749.505 | AK12: 477286.58 | AL12: 126401.56 | AM12: 978678.55 | AN12: 49938.495 | AO12: 40769.955 | AP12: 210534.62 | AQ12: 150218.84 | AR12: 75793.498 | AS12: 145536.92 | AT12: 70506.932 | AU12: 19916.16 | AV12: 35361.824 | AW12: 282260.07 | AX12: 47370.516
A13: RP_pos_176_07085a4_942 | B13: 3-indoleacetic acid | C13: 1210899.7 | D13: 1104270.3 | E13: 1879646.7 | F13: 159049.49 | G13: 609169.14 | H13: 682965.73 | I13: 1331622.1 | J13: 1531413.7 | K13: 789876.61 | L13: 1238259.8 | M13: 234445.71 | N13: 972124.82 | O13: 1022877.5 | P13: 519583.42 | Q13: 665611.36 | R13: 1213114 | S13: 1832430 | T13: 942088.08 | U13: 1840410.5 | V13: 465173.68 | W13: 1228987.1 | X13: 962111.74 | Y13: 779079.87 | Z13: 585840.8 | AA13: 131669.75 | AB13: 965229.34 | AC13: 1894816.6 | AD13: 2348312.8 | AE13: 3092624.9 | AF13: 426839.89 | AG13: 2878586.2 | AH13: 1761382.6 | AI13: 2289053.6 | AJ13: 1429620.2 | AK13: 1144727.1 | AL13: 2914485.9 | AM13: 127179.37 | AN13: 1944807.7 | AO13: 725103.63 | AP13: 1412685.2 | AQ13: 1238638.4 | AR13: 1388206.7 | AS13: 1016907.4 | AT13: 3970495.7 | AU13: 2074373.4 | AV13: 1109926.5 | AW13: 1218050.4 | AX13: 1474044.1
... A189: RP_neg_271_22879a10_298 | B189: FA 16:0;O | C189: 1733637.1 | D189: 2858251.5 | E189: 1838506.3 | F189: 1442801 | G189: 2064622.4 | H189: 1741381.9 | I189: 1379492.3 | J189: 1037310.9 | K189: 2838142.2 | L189: 1246351.6 | M189: 2450289 | N189: 1924476.3 | O189: 1490256.5 | P189: 3547058.2 | Q189: 2023078.2 | R189: 1176154.3 | S189: 1213819.7 | T189: 1300389.7 | U189: 1387669.5 | V189: 3356398.3 | W189: 2215401.3 | X189: 3195305.2 | Y189: 2397038.6 | Z189: 1924800.8 | AA189: 3384237.7 | AB189: 4526468.4 | AC189: 3487993.8 | AD189: 2216979.3 | AE189: 2314815.4 | AF189: 6131925.5 | AG189: 2118704.9 | AH189: 2876641.4 | AI189: 3330982.2 | AJ189: 0 | AK189: 3374554.9 | AL189: 2666418.6 | AM189: 5042469.2 | AN189: 3179143.9 | AO189: 2174119.1 | AP189: 5489950.3 | AQ189: 6039904.8 | AR189: 2554132.4 | AS189: 4711378.9 | AT189: 2660297.3 | AU189: 6263785.9 | AV189: 6280329.9 | AW189: 6535298 | AX189: 6300859

Sheet Normalized Abundances
A1: Feature_ID | B1: Curated_ID | C1: K107dI | D1: K069dI | E1: K105dI | F1: K064dI | G1: K063dI | H1: K101dI | I1: K106dI | J1: K113dI | K1: K062dI | L1: K109dI | M1: K074dI | N1: K114dI | O1: K103dI | P1: K070dI | Q1: K079dI | R1: K115dI | S1: K120dI | T1: K080dI | U1: K116dI | V1: K067dI | W1: K077dI | X1: K073dI | Y1: K071dI | Z1: K117dI | AA1: K064dH | AB1: K071dH | AC1: K106dH | AD1: K107dH | AE1: K116dH | AF1: K067dH | AG1: K120dH | AH1: K115dH | AI1: K109dH | AJ1: K114dH | AK1: K080dH | AL1: K113dH | AM1: K074dH | AN1: K103dH | AO1: K117dH | AP1: K077dH | AQ1: K063dH | AR1: K101dH | AS1: K079dH | AT1: K105dH | AU1: K069dH | AV1: K070dH | AW1: K062dH | AX1: K073dH
A2: HILIC_pos_282_1199a4_375 | B2: 1-Methyladenosine | C2: {=('Reordered Abundances'!C2-AVERAGE('Reordered Abundances'!$C2:$AX2))/STDEV('Reordered Abundances'!$C2:$AX2)} -> 1.2145039 | D2: {=('Reordered Abundances'!D2-AVERAGE('Reordered Abundances'!$C2:$AX2))/STDEV('Reordered Abundances'!$C2:$AX2)} -> 1.1103714 | E2: {=('Reordered Abundances'!E2-AVERAGE('Reordered Abundances'!$C2:$AX2))/STDEV('Reordered Abundances'!$C2:$AX2)} -> 0.86008149 | F2: {=('Reordered Abundances'!F2-AVERAGE('Reordered Abundances'!$C2:$AX2))/STDEV('Reordered Abundances'!$C2:$AX2)} -> 0.55735422 | G2: {=('Reordered Abundances'!G2-AVERAGE('Reordered Abundances'!$C2:$AX2))/STDEV('Reordered Abundances'!$C2:$AX2)} -> 1.1152449 | H2: {=('Reordered Abundances'!H2-AVERAGE('Reordered Abundances'!$C2:$AX2))/STDEV('Reordered Abundances'!$C2:$AX2)} -> 0.89532701 | I2: {=('Reordered Abundances'!I2-AVERAGE('Reordered Abundances'!$C2:$AX2))/STDEV('Reordered Abundances'!$C2:$AX2)} -> 0.37460766 | J2: {=('Reordered Abundances'!J2-AVERAGE('Reordered Abundances'!$C2:$AX2))/STDEV('Reordered Abundances'!$C2:$AX2)} -> 0.64911623 | ... AX2: {=('Reordered Abundances'!AX2-AVERAGE('Reordered Abundances'!$C2:$AX2))/STDEV('Reordered Abundances'!$C2:$AX2)} -> -1.0898667
A3: HILIC_pos_204_12305a3_15 | B3: Acetylcarnitine | C3: {=('Reordered Abundances'!C3-AVERAGE('Reordered Abundances'!$C3:$AX3))/STDEV('Reordered Abundances'!$C3:$AX3)} -> 0.24276151 | D3: {=('Reordered Abundances'!D3-AVERAGE('Reordered Abundances'!$C3:$AX3))/STDEV('Reordered Abundances'!$C3:$AX3)} -> 0.39515207 | E3: {=('Reordered Abundances'!E3-AVERAGE('Reordered Abundances'!$C3:$AX3))/STDEV('Reordered Abundances'!$C3:$AX3)} -> 0.10855816 | F3: {=('Reordered Abundances'!F3-AVERAGE('Reordered Abundances'!$C3:$AX3))/STDEV('Reordered Abundances'!$C3:$AX3)} -> 2.4805727 | G3: {=('Reordered Abundances'!G3-AVERAGE('Reordered Abundances'!$C3:$AX3))/STDEV('Reordered Abundances'!$C3:$AX3)} -> 0.60794747 | H3: {=('Reordered Abundances'!H3-AVERAGE('Reordered Abundances'!$C3:$AX3))/STDEV('Reordered Abundances'!$C3:$AX3)} -> 0.63269209 | I3: {=('Reordered Abundances'!I3-AVERAGE('Reordered Abundances'!$C3:$AX3))/STDEV('Reordered Abundances'!$C3:$AX3)} -> 0.48038325 | J3: {=('Reordered Abundances'!J3-AVERAGE('Reordered Abundances'!$C3:$AX3))/STDEV('Reordered Abundances'!$C3:$AX3)} -> 0.58294045 | ... AX3: {=('Reordered Abundances'!AX3-AVERAGE('Reordered Abundances'!$C3:$AX3))/STDEV('Reordered Abundances'!$C3:$AX3)} -> -0.96801296
A4: RP_pos_162_09132a4_953 | B4: Tryptophol | C4: {=('Reordered Abundances'!C4-AVERAGE('Reordered Abundances'!$C4:$AX4))/STDEV('Reordered Abundances'!$C4:$AX4)} -> 1.2570968 | D4: {=('Reordered Abundances'!D4-AVERAGE('Reordered Abundances'!$C4:$AX4))/STDEV('Reordered Abundances'!$C4:$AX4)} -> 0.58593753 | E4: {=('Reordered Abundances'!E4-AVERAGE('Reordered Abundances'!$C4:$AX4))/STDEV('Reordered Abundances'!$C4:$AX4)} -> 0.20229159 | F4: {=('Reordered Abundances'!F4-AVERAGE('Reordered Abundances'!$C4:$AX4))/STDEV('Reordered Abundances'!$C4:$AX4)} -> -1.3432425 | G4: {=('Reordered Abundances'!G4-AVERAGE('Reordered Abundances'!$C4:$AX4))/STDEV('Reordered Abundances'!$C4:$AX4)} -> 1.0123299 | H4: {=('Reordered Abundances'!H4-AVERAGE('Reordered Abundances'!$C4:$AX4))/STDEV('Reordered Abundances'!$C4:$AX4)} -> 1.3809559 | I4: {=('Reordered Abundances'!I4-AVERAGE('Reordered Abundances'!$C4:$AX4))/STDEV('Reordered Abundances'!$C4:$AX4)} -> -0.81090782 | J4: {=('Reordered Abundances'!J4-AVERAGE('Reordered Abundances'!$C4:$AX4))/STDEV('Reordered Abundances'!$C4:$AX4)} -> 1.1344063 | ... AX4: {=('Reordered Abundances'!AX4-AVERAGE('Reordered Abundances'!$C4:$AX4))/STDEV('Reordered Abundances'!$C4:$AX4)} -> -0.48215215
A5: RP_pos_161_10786a2_57 | B5: Tryptamine | C5: {=('Reordered Abundances'!C5-AVERAGE('Reordered Abundances'!$C5:$AX5))/STDEV('Reordered Abundances'!$C5:$AX5)} -> -0.31430844 | D5: {=('Reordered Abundances'!D5-AVERAGE('Reordered Abundances'!$C5:$AX5))/STDEV('Reordered Abundances'!$C5:$AX5)} -> -0.82840258 | E5: {=('Reordered Abundances'!E5-AVERAGE('Reordered Abundances'!$C5:$AX5))/STDEV('Reordered Abundances'!$C5:$AX5)} -> -0.70954254 | F5: {=('Reordered Abundances'!F5-AVERAGE('Reordered Abundances'!$C5:$AX5))/STDEV('Reordered Abundances'!$C5:$AX5)} -> -0.93341914 | G5: {=('Reordered Abundances'!G5-AVERAGE('Reordered Abundances'!$C5:$AX5))/STDEV('Reordered Abundances'!$C5:$AX5)} -> -1.1133749 | H5: {=('Reordered Abundances'!H5-AVERAGE('Reordered Abundances'!$C5:$AX5))/STDEV('Reordered Abundances'!$C5:$AX5)} -> -1.1206076 | I5: {=('Reordered Abundances'!I5-AVERAGE('Reordered Abundances'!$C5:$AX5))/STDEV('Reordered Abundances'!$C5:$AX5)} -> -0.50869969 | J5: {=('Reordered Abundances'!J5-AVERAGE('Reordered Abundances'!$C5:$AX5))/STDEV('Reordered Abundances'!$C5:$AX5)} -> 0.023116153 | ... AX5: {=('Reordered Abundances'!AX5-AVERAGE('Reordered Abundances'!$C5:$AX5))/STDEV('Reordered Abundances'!$C5:$AX5)} -> 0.30584934
A6: RP_pos_177_10252a1_429 | B6: Serotonin | C6: {=('Reordered Abundances'!C6-AVERAGE('Reordered Abundances'!$C6:$AX6))/STDEV('Reordered Abundances'!$C6:$AX6)} -> 1.1751712 | D6: {=('Reordered Abundances'!D6-AVERAGE('Reordered Abundances'!$C6:$AX6))/STDEV('Reordered Abundances'!$C6:$AX6)} -> 1.7760922 | E6: {=('Reordered Abundances'!E6-AVERAGE('Reordered Abundances'!$C6:$AX6))/STDEV('Reordered Abundances'!$C6:$AX6)} -> 0.46087899 | F6: {=('Reordered Abundances'!F6-AVERAGE('Reordered Abundances'!$C6:$AX6))/STDEV('Reordered Abundances'!$C6:$AX6)} -> 0.64568007 | G6: {=('Reordered Abundances'!G6-AVERAGE('Reordered Abundances'!$C6:$AX6))/STDEV('Reordered Abundances'!$C6:$AX6)} -> 0.80584427 | H6: {=('Reordered Abundances'!H6-AVERAGE('Reordered Abundances'!$C6:$AX6))/STDEV('Reordered Abundances'!$C6:$AX6)} -> 1.2100631 | I6: {=('Reordered Abundances'!I6-AVERAGE('Reordered Abundances'!$C6:$AX6))/STDEV('Reordered Abundances'!$C6:$AX6)} -> 1.5644683 | J6: {=('Reordered Abundances'!J6-AVERAGE('Reordered Abundances'!$C6:$AX6))/STDEV('Reordered Abundances'!$C6:$AX6)} -> 0.55409318 | ... AX6: {=('Reordered Abundances'!AX6-AVERAGE('Reordered Abundances'!$C6:$AX6))/STDEV('Reordered Abundances'!$C6:$AX6)} -> -0.90511301
A7: RP_pos_209_09212a1_716 | B7: Kynurenine | C7: {=('Reordered Abundances'!C7-AVERAGE('Reordered Abundances'!$C7:$AX7))/STDEV('Reordered Abundances'!$C7:$AX7)} -> 1.6767756 | D7: {=('Reordered Abundances'!D7-AVERAGE('Reordered Abundances'!$C7:$AX7))/STDEV('Reordered Abundances'!$C7:$AX7)} -> 0.30707974 | E7: {=('Reordered Abundances'!E7-AVERAGE('Reordered Abundances'!$C7:$AX7))/STDEV('Reordered Abundances'!$C7:$AX7)} -> 0.24827964 | F7: {=('Reordered Abundances'!F7-AVERAGE('Reordered Abundances'!$C7:$AX7))/STDEV('Reordered Abundances'!$C7:$AX7)} -> 0.67214312 | G7: {=('Reordered Abundances'!G7-AVERAGE('Reordered Abundances'!$C7:$AX7))/STDEV('Reordered Abundances'!$C7:$AX7)} -> 0.97561564 | H7: {=('Reordered Abundances'!H7-AVERAGE('Reordered Abundances'!$C7:$AX7))/STDEV('Reordered Abundances'!$C7:$AX7)} -> 1.0161374 | I7: {=('Reordered Abundances'!I7-AVERAGE('Reordered Abundances'!$C7:$AX7))/STDEV('Reordered Abundances'!$C7:$AX7)} -> -0.39754765 | J7: {=('Reordered Abundances'!J7-AVERAGE('Reordered Abundances'!$C7:$AX7))/STDEV('Reordered Abundances'!$C7:$AX7)} -> 0.6720683 | ... AX7: {=('Reordered Abundances'!AX7-AVERAGE('Reordered Abundances'!$C7:$AX7))/STDEV('Reordered Abundances'!$C7:$AX7)} -> -0.85656889
A8: RP_pos_268_10461a1_422 | B8: Adenosine | C8: {=('Reordered Abundances'!C8-AVERAGE('Reordered Abundances'!$C8:$AX8))/STDEV('Reordered Abundances'!$C8:$AX8)} -> 0.019493891 | D8: {=('Reordered Abundances'!D8-AVERAGE('Reordered Abundances'!$C8:$AX8))/STDEV('Reordered Abundances'!$C8:$AX8)} -> 0.83359711 | E8: {=('Reordered Abundances'!E8-AVERAGE('Reordered Abundances'!$C8:$AX8))/STDEV('Reordered Abundances'!$C8:$AX8)} -> 0.78095054 | F8: {=('Reordered Abundances'!F8-AVERAGE('Reordered Abundances'!$C8:$AX8))/STDEV('Reordered Abundances'!$C8:$AX8)} -> 1.0433341 | G8: {=('Reordered Abundances'!G8-AVERAGE('Reordered Abundances'!$C8:$AX8))/STDEV('Reordered Abundances'!$C8:$AX8)} -> 1.2681298 | H8: {=('Reordered Abundances'!H8-AVERAGE('Reordered Abundances'!$C8:$AX8))/STDEV('Reordered Abundances'!$C8:$AX8)} -> 0.42147868 | I8: {=('Reordered Abundances'!I8-AVERAGE('Reordered Abundances'!$C8:$AX8))/STDEV('Reordered Abundances'!$C8:$AX8)} -> 0.72060259 | J8: {=('Reordered Abundances'!J8-AVERAGE('Reordered Abundances'!$C8:$AX8))/STDEV('Reordered Abundances'!$C8:$AX8)} -> 0.47636057 | ... AX8: {=('Reordered Abundances'!AX8-AVERAGE('Reordered Abundances'!$C8:$AX8))/STDEV('Reordered Abundances'!$C8:$AX8)} -> -0.96581342
A9: HILIC_pos_284_09863a4_18 | B9: Guanosine | C9: {=('Reordered Abundances'!C9-AVERAGE('Reordered Abundances'!$C9:$AX9))/STDEV('Reordered Abundances'!$C9:$AX9)} -> 0.85734605 | D9: {=('Reordered Abundances'!D9-AVERAGE('Reordered Abundances'!$C9:$AX9))/STDEV('Reordered Abundances'!$C9:$AX9)} -> 0.67556022 | E9: {=('Reordered Abundances'!E9-AVERAGE('Reordered Abundances'!$C9:$AX9))/STDEV('Reordered Abundances'!$C9:$AX9)} -> 1.3278717 | F9: {=('Reordered Abundances'!F9-AVERAGE('Reordered Abundances'!$C9:$AX9))/STDEV('Reordered Abundances'!$C9:$AX9)} -> 1.2247826 | G9: {=('Reordered Abundances'!G9-AVERAGE('Reordered Abundances'!$C9:$AX9))/STDEV('Reordered Abundances'!$C9:$AX9)} -> 0.77073361 | H9: {=('Reordered Abundances'!H9-AVERAGE('Reordered Abundances'!$C9:$AX9))/STDEV('Reordered Abundances'!$C9:$AX9)} -> 0.63270772 | I9: {=('Reordered Abundances'!I9-AVERAGE('Reordered Abundances'!$C9:$AX9))/STDEV('Reordered Abundances'!$C9:$AX9)} -> 0.47355361 | J9: {=('Reordered Abundances'!J9-AVERAGE('Reordered Abundances'!$C9:$AX9))/STDEV('Reordered Abundances'!$C9:$AX9)} -> 0.68046372 | ... AX9: {=('Reordered Abundances'!AX9-AVERAGE('Reordered Abundances'!$C9:$AX9))/STDEV('Reordered Abundances'!$C9:$AX9)} -> -1.0752416
A10: HILIC_pos_348_07047a7_608 | B10: Adenylic acid (AMP) | C10: {=('Reordered Abundances'!C10-AVERAGE('Reordered Abundances'!$C10:$AX10))/STDEV('Reordered Abundances'!$C10:$AX10)} -> 0.37248353 | D10: {=('Reordered Abundances'!D10-AVERAGE('Reordered Abundances'!$C10:$AX10))/STDEV('Reordered Abundances'!$C10:$AX10)} -> 1.2912522 | E10: {=('Reordered Abundances'!E10-AVERAGE('Reordered Abundances'!$C10:$AX10))/STDEV('Reordered Abundances'!$C10:$AX10)} -> 0.14790542 | F10: {=('Reordered Abundances'!F10-AVERAGE('Reordered Abundances'!$C10:$AX10))/STDEV('Reordered Abundances'!$C10:$AX10)} -> 0.37479768 | G10: {=('Reordered Abundances'!G10-AVERAGE('Reordered Abundances'!$C10:$AX10))/STDEV('Reordered Abundances'!$C10:$AX10)} -> 0.65145594 | H10: {=('Reordered Abundances'!H10-AVERAGE('Reordered Abundances'!$C10:$AX10))/STDEV('Reordered Abundances'!$C10:$AX10)} -> 0.43761557 | I10: {=('Reordered Abundances'!I10-AVERAGE('Reordered Abundances'!$C10:$AX10))/STDEV('Reordered Abundances'!$C10:$AX10)} -> 0.59624834 | J10: {=('Reordered Abundances'!J10-AVERAGE('Reordered Abundances'!$C10:$AX10))/STDEV('Reordered Abundances'!$C10:$AX10)} -> -0.079556061 | ... AX10: {=('Reordered Abundances'!AX10-AVERAGE('Reordered Abundances'!$C10:$AX10))/STDEV('Reordered Abundances'!$C10:$AX10)} -> -0.85914605
A11: RP_neg_201_1131a6_45 | B11: Sebacic acid (aka decanedioic acid) | C11: {=('Reordered Abundances'!C11-AVERAGE('Reordered Abundances'!$C11:$AX11))/STDEV('Reordered Abundances'!$C11:$AX11)} -> -0.90690346 | D11: {=('Reordered Abundances'!D11-AVERAGE('Reordered Abundances'!$C11:$AX11))/STDEV('Reordered Abundances'!$C11:$AX11)} -> -0.65206403 | E11: {=('Reordered Abundances'!E11-AVERAGE('Reordered Abundances'!$C11:$AX11))/STDEV('Reordered Abundances'!$C11:$AX11)} -> 0.018040974 | F11: {=('Reordered Abundances'!F11-AVERAGE('Reordered Abundances'!$C11:$AX11))/STDEV('Reordered Abundances'!$C11:$AX11)} -> -0.17456115 | G11: {=('Reordered Abundances'!G11-AVERAGE('Reordered Abundances'!$C11:$AX11))/STDEV('Reordered Abundances'!$C11:$AX11)} -> -0.72761575 | H11: {=('Reordered Abundances'!H11-AVERAGE('Reordered Abundances'!$C11:$AX11))/STDEV('Reordered Abundances'!$C11:$AX11)} -> -0.37044535 | I11: {=('Reordered Abundances'!I11-AVERAGE('Reordered Abundances'!$C11:$AX11))/STDEV('Reordered Abundances'!$C11:$AX11)} -> -0.60199674 | J11: {=('Reordered Abundances'!J11-AVERAGE('Reordered Abundances'!$C11:$AX11))/STDEV('Reordered Abundances'!$C11:$AX11)} -> -0.67067004 | ... AX11: {=('Reordered Abundances'!AX11-AVERAGE('Reordered Abundances'!$C11:$AX11))/STDEV('Reordered Abundances'!$C11:$AX11)} -> 0.81811144
A12: RP_pos_218_13914a1_324 | B12: CAR 3:0 | C12: {=('Reordered Abundances'!C12-AVERAGE('Reordered Abundances'!$C12:$AX12))/STDEV('Reordered Abundances'!$C12:$AX12)} -> 0.98176468 | D12: {=('Reordered Abundances'!D12-AVERAGE('Reordered Abundances'!$C12:$AX12))/STDEV('Reordered Abundances'!$C12:$AX12)} -> 0.024527166 | E12: {=('Reordered Abundances'!E12-AVERAGE('Reordered Abundances'!$C12:$AX12))/STDEV('Reordered Abundances'!$C12:$AX12)} -> 0.40586588 | F12: {=('Reordered Abundances'!F12-AVERAGE('Reordered Abundances'!$C12:$AX12))/STDEV('Reordered Abundances'!$C12:$AX12)} -> 0.031838631 | G12: {=('Reordered Abundances'!G12-AVERAGE('Reordered Abundances'!$C12:$AX12))/STDEV('Reordered Abundances'!$C12:$AX12)} -> 0.65695908 | H12: {=('Reordered Abundances'!H12-AVERAGE('Reordered Abundances'!$C12:$AX12))/STDEV('Reordered Abundances'!$C12:$AX12)} -> 0.31718002 | I12: {=('Reordered Abundances'!I12-AVERAGE('Reordered Abundances'!$C12:$AX12))/STDEV('Reordered Abundances'!$C12:$AX12)} -> 0.6449923 | J12: {=('Reordered Abundances'!J12-AVERAGE('Reordered Abundances'!$C12:$AX12))/STDEV('Reordered Abundances'!$C12:$AX12)} -> 0.95667517 | ... AX12: {=('Reordered Abundances'!AX12-AVERAGE('Reordered Abundances'!$C12:$AX12))/STDEV('Reordered Abundances'!$C12:$AX12)} -> -0.89608469
A13: RP_pos_176_07085a4_942 | B13: 3-indoleacetic acid | C13: {=('Reordered Abundances'!C13-AVERAGE('Reordered Abundances'!$C13:$AX13))/STDEV('Reordered Abundances'!$C13:$AX13)} -> -0.1198846 | D13: {=('Reordered Abundances'!D13-AVERAGE('Reordered Abundances'!$C13:$AX13))/STDEV('Reordered Abundances'!$C13:$AX13)} -> -0.25168069 | E13: {=('Reordered Abundances'!E13-AVERAGE('Reordered Abundances'!$C13:$AX13))/STDEV('Reordered Abundances'!$C13:$AX13)} -> 0.70670049 | F13: {=('Reordered Abundances'!F13-AVERAGE('Reordered Abundances'!$C13:$AX13))/STDEV('Reordered Abundances'!$C13:$AX13)} -> -1.419993 | G13: {=('Reordered Abundances'!G13-AVERAGE('Reordered Abundances'!$C13:$AX13))/STDEV('Reordered Abundances'!$C13:$AX13)} -> -0.86363586 | H13: {=('Reordered Abundances'!H13-AVERAGE('Reordered Abundances'!$C13:$AX13))/STDEV('Reordered Abundances'!$C13:$AX13)} -> -0.77242177 | I13: {=('Reordered Abundances'!I13-AVERAGE('Reordered Abundances'!$C13:$AX13))/STDEV('Reordered Abundances'!$C13:$AX13)} -> 0.029330776 | J13: {=('Reordered Abundances'!J13-AVERAGE('Reordered Abundances'!$C13:$AX13))/STDEV('Reordered Abundances'!$C13:$AX13)} -> 0.27627734 | ... AX13: {=('Reordered Abundances'!AX13-AVERAGE('Reordered Abundances'!$C13:$AX13))/STDEV('Reordered Abundances'!$C13:$AX13)} -> 0.20536737
... A189: RP_neg_271_22879a10_298 | B189: FA 16:0;O | C189: {=('Reordered Abundances'!C189-AVERAGE('Reordered Abundances'!$C189:$AX189))/STDEV('Reordered Abundances'!$C189:$AX189)} -> -0.73299724 | D189: {=('Reordered Abundances'!D189-AVERAGE('Reordered Abundances'!$C189:$AX189))/STDEV('Reordered Abundances'!$C189:$AX189)} -> -0.053473593 | E189: {=('Reordered Abundances'!E189-AVERAGE('Reordered Abundances'!$C189:$AX189))/STDEV('Reordered Abundances'!$C189:$AX189)} -> -0.66963231 | F189: {=('Reordered Abundances'!F189-AVERAGE('Reordered Abundances'!$C189:$AX189))/STDEV('Reordered Abundances'!$C189:$AX189)} -> -0.90872857 | G189: {=('Reordered Abundances'!G189-AVERAGE('Reordered Abundances'!$C189:$AX189))/STDEV('Reordered Abundances'!$C189:$AX189)} -> -0.53300659 | H189: {=('Reordered Abundances'!H189-AVERAGE('Reordered Abundances'!$C189:$AX189))/STDEV('Reordered Abundances'!$C189:$AX189)} -> -0.72831764 | I189: {=('Reordered Abundances'!I189-AVERAGE('Reordered Abundances'!$C189:$AX189))/STDEV('Reordered Abundances'!$C189:$AX189)} -> -0.94698149 | J189: {=('Reordered Abundances'!J189-AVERAGE('Reordered Abundances'!$C189:$AX189))/STDEV('Reordered Abundances'!$C189:$AX189)} -> -1.1537371 | ... AX189: {=('Reordered Abundances'!AX189-AVERAGE('Reordered Abundances'!$C189:$AX189))/STDEV('Reordered Abundances'!$C189:$AX189)} -> 2.0266467
