Workbook

Sheet Abundances
A1: Feature_ID | B1: J011eJ | C1: J016eJ | D1: J005eJ | E1: J014eJ | F1: J003eJ | G1: J002eJ | H1: J012eJ | I1: J015eJ | J1: J018eJ | K1: J001eJ | L1: J017eJ | M1: J008eJ | N1: J019eJ | O1: J013eJ | P1: J006eJ | Q1: J010eJ | R1: J020eJ | S1: J023eJ | T1: J024eJ | U1: J021eJ | V1: J009eJ | W1: J022eJ | X1: J007eJ | Y1: J004eJ | Z1: J003eI | AA1: J006eI | AB1: J016eI | AC1: J017eI | AD1: J024eI | AE1: J022eI | AF1: J019eI | AG1: J021eI | AH1: J018eI | AI1: J020eI | AJ1: J012eI | AK1: J015eI | AL1: J009eI | AM1: J014eI | AN1: J023eI | AO1: J011eI | AP1: J002eI | AQ1: J013eI | AR1: J004eI | AS1: J008eI | AT1: J007eI | AU1: J005eI | AV1: J001eI
A2: HILIC_neg_59_01351a1_44 | B2: 43608.493 | C2: 37302.09 | D2: 10196.973 | E2: 20029.784 | F2: 18448.384 | G2: 10143.848 | H2: 27525.225 | I2: 41759.903 | J2: 12119.377 | K2: 17788.725 | L2: 19419.336 | M2: 63799.078 | N2: 10283.022 | O2: 31650.158 | P2: 28797.336 | Q2: 35636.562 | R2: 9670.2542 | S2: 33729.815 | T2: 24206.092 | U2: 8408.3212 | V2: 13138.174 | W2: 22755.621 | X2: 11827.366 | Y2: 24355.383 | Z2: 27564.701 | AA2: 56772.274 | AB2: 64952.862 | AC2: 38153.182 | AD2: 63018.696 | AE2: 37817.016 | AF2: 14840.863 | AG2: 9532.2261 | AH2: 16058.499 | AI2: 8713.1123 | AJ2: 47410.269 | AK2: 39918.253 | AL2: 21297.924 | AM2: 36125.49 | AN2: 57196.886 | AO2: 123328.47 | AP2: 13918.44 | AQ2: 58960.624 | AR2: 71124.609 | AS2: 179379.33 | AT2: 20339.677 | AU2: 11102.657 | AV2: 41605.463
A3: HILIC_neg_88_04021a6_65 | B3: 121059.02 | C3: 114191.11 | D3: 185181.13 | E3: 134413.1 | F3: 154665.82 | G3: 179444.77 | H3: 144450.11 | I3: 138926.25 | J3: 152441.07 | K3: 167965.6 | L3: 134403.52 | M3: 133784.28 | N3: 177132.26 | O3: 188687.19 | P3: 147540.66 | Q3: 166613.5 | R3: 192913.14 | S3: 75575.95 | T3: 190293.61 | U3: 144841.25 | V3: 177811.38 | W3: 103476.11 | X3: 163922.09 | Y3: 145474.79 | Z3: 45537.628 | AA3: 18333.833 | AB3: 36105.165 | AC3: 31499.903 | AD3: 27113.523 | AE3: 10532.183 | AF3: 43133.507 | AG3: 27517.656 | AH3: 10872.274 | AI3: 17353.752 | AJ3: 16957.175 | AK3: 9453.639 | AL3: 99725.675 | AM3: 12972.851 | AN3: 10066.255 | AO3: 8293.9943 | AP3: 35928.252 | AQ3: 35867.097 | AR3: 40958.098 | AS3: 15410.737 | AT3: 35586.751 | AU3: 81378.05 | AV3: 76959.595
A4: HILIC_neg_89_02456a1_407 | B4: 10830226 | C4: 10176330 | D4: 13034415 | E4: 13702885 | F4: 14182728 | G4: 15267276 | H4: 11367971 | I4: 13031829 | J4: 13174690 | K4: 14713194 | L4: 19634387 | M4: 20095463 | N4: 21619802 | O4: 13843618 | P4: 14934733 | Q4: 15716611 | R4: 14865396 | S4: 17228572 | T4: 14833957 | U4: 13686177 | V4: 12987921 | W4: 11394261 | X4: 13243894 | Y4: 15990693 | Z4: 220379.73 | AA4: 334333.5 | AB4: 596960.57 | AC4: 19907168 | AD4: 11389376 | AE4: 1663949.4 | AF4: 7787522.8 | AG4: 106865.29 | AH4: 110111.94 | AI4: 168732.85 | AJ4: 1210448.6 | AK4: 1797599.6 | AL4: 83964.297 | AM4: 553668.12 | AN4: 9069300.4 | AO4: 5351684.1 | AP4: 389973.62 | AQ4: 1661339.8 | AR4: 11486078 | AS4: 16494239 | AT4: 466287.06 | AU4: 254962.83 | AV4: 473285.85
A5: HILIC_neg_102_05624a6_271 | B5: 239878.9 | C5: 297906.67 | D5: 342976.14 | E5: 269566.68 | F5: 326158.96 | G5: 298095.84 | H5: 308042.43 | I5: 276169.02 | J5: 340685.12 | K5: 332807.43 | L5: 286624.37 | M5: 258386.96 | N5: 318040.95 | O5: 365284.57 | P5: 288121.7 | Q5: 305961.13 | R5: 310439.83 | S5: 261161.58 | T5: 311289.31 | U5: 301447.64 | V5: 339132.67 | W5: 255891.67 | X5: 322714.47 | Y5: 238278.8 | Z5: 66192.771 | AA5: 35259.55 | AB5: 59593.317 | AC5: 61153.026 | AD5: 54870.036 | AE5: 21219.767 | AF5: 58324.613 | AG5: 45249.477 | AH5: 21939.847 | AI5: 24980.796 | AJ5: 29218.703 | AK5: 15376.069 | AL5: 124645.3 | AM5: 29943.09 | AN5: 17828.539 | AO5: 42419.246 | AP5: 47444.747 | AQ5: 63416.194 | AR5: 56249.962 | AS5: 44868.853 | AT5: 41572.29 | AU5: 71810.151 | AV5: 88738.077
A6: HILIC_neg_102_96039a3_152 | B6: 60878.334 | C6: 47300.686 | D6: 54130.056 | E6: 34431.966 | F6: 95719.191 | G6: 57582.763 | H6: 71015.699 | I6: 68042.862 | J6: 51511.393 | K6: 60667.205 | L6: 48638.227 | M6: 38190.263 | N6: 37162.478 | O6: 35233.393 | P6: 45949.014 | Q6: 21450.75 | R6: 44627.686 | S6: 46723.526 | T6: 53389.373 | U6: 26392.129 | V6: 55031.195 | W6: 51133.869 | X6: 42259.793 | Y6: 27031.842 | Z6: 26637.539 | AA6: 26404.666 | AB6: 27303.526 | AC6: 8879.765 | AD6: 42378.105 | AE6: 34172.185 | AF6: 41681.225 | AG6: 28922.096 | AH6: 18682.689 | AI6: 27226.666 | AJ6: 20033.84 | AK6: 36991.306 | AL6: 22771.473 | AM6: 41147.014 | AN6: 32760.718 | AO6: 38573.801 | AP6: 6101.5627 | AQ6: 13560.249 | AR6: 22644.209 | AS6: 12058.542 | AT6: 22141.942 | AU6: 31094.932 | AV6: 20428.836
A7: HILIC_neg_103_03951a0_992 | B7: 118003.13 | C7: 158233.47 | D7: 67036.902 | E7: 138951.18 | F7: 73465.673 | G7: 74889.639 | H7: 116872.36 | I7: 160130.11 | J7: 57963.791 | K7: 90742.331 | L7: 376426.09 | M7: 201432.61 | N7: 120082.02 | O7: 124747.83 | P7: 84564.55 | Q7: 204833.95 | R7: 61151.039 | S7: 536966.62 | T7: 208406.34 | U7: 73661.975 | V7: 85499.177 | W7: 181689.05 | X7: 57036.063 | Y7: 235526.31 | Z7: 57333.929 | AA7: 50892.431 | AB7: 256077.68 | AC7: 729949.75 | AD7: 411049.74 | AE7: 324813.39 | AF7: 164112.35 | AG7: 14163.198 | AH7: 12712.349 | AI7: 13639.946 | AJ7: 133428.07 | AK7: 176229.62 | AL7: 39139.249 | AM7: 149397.61 | AN7: 921282.1 | AO7: 298862.97 | AP7: 27772.857 | AQ7: 77202.937 | AR7: 422283.73 | AS7: 333693.58 | AT7: 19496.249 | AU7: 33765.867 | AV7: 56089.061
A8: HILIC_neg_104_03509a6_07 | B8: 54778.092 | C8: 54423.817 | D8: 80661.626 | E8: 62759.086 | F8: 75478.9 | G8: 72353.979 | H8: 48909.083 | I8: 53362.272 | J8: 54160.346 | K8: 75087.714 | L8: 57683.054 | M8: 71411.144 | N8: 69696.623 | O8: 77564.573 | P8: 46062.078 | Q8: 60161.937 | R8: 58791.522 | S8: 49695.617 | T8: 57035.88 | U8: 73185.742 | V8: 61255.457 | W8: 59063.31 | X8: 57813.603 | Y8: 71650.618 | Z8: 10915.99 | AA8: 7555.3756 | AB8: 9742.1883 | AC8: 11346.765 | AD8: 13967.728 | AE8: 11773.52 | AF8: 9360.7226 | AG8: 8574.4631 | AH8: 9308.7186 | AI8: 9158.8391 | AJ8: 10178.645 | AK8: 9249.3698 | AL8: 9948.949 | AM8: 8151.1784 | AN8: 11166.548 | AO8: 10551.313 | AP8: 8473.8933 | AQ8: 13918.781 | AR8: 11625.184 | AS8: 10331.02 | AT8: 12204.855 | AU8: 9496.9756 | AV8: 13171.102
A9: HILIC_neg_117_05537a0_773 | B9: 197578.89 | C9: 369976.45 | D9: 32339.063 | E9: 329890.13 | F9: 51098.377 | G9: 87004.057 | H9: 259935.78 | I9: 389187.42 | J9: 95287.636 | K9: 148371.53 | L9: 533741.68 | M9: 37458.736 | N9: 141720.33 | O9: 107982.35 | P9: 75980.957 | Q9: 262872.96 | R9: 34594.339 | S9: 782342.83 | T9: 566024.23 | U9: 26020.565 | V9: 114912.69 | W9: 355509.04 | X9: 58474.55 | Y9: 381786.25 | Z9: 85007.358 | AA9: 114349.95 | AB9: 706636.11 | AC9: 920431.58 | AD9: 1125165.5 | AE9: 650191.2 | AF9: 395584.71 | AG9: 53575.889 | AH9: 172544.23 | AI9: 24667.318 | AJ9: 468163.4 | AK9: 578463.71 | AL9: 152052.61 | AM9: 754604.51 | AN9: 1190926.4 | AO9: 466765.32 | AP9: 123912.07 | AQ9: 122530.31 | AR9: 1010811.2 | AS9: 169560.55 | AT9: 72493.859 | AU9: 16272.005 | AV9: 269807.71
A10: HILIC_neg_118_05101a5_702 | B10: 348623.92 | C10: 298993.98 | D10: 473913.66 | E10: 537685.79 | F10: 321805.68 | G10: 487629.98 | H10: 446392.39 | I10: 468991.81 | J10: 346533.49 | K10: 313144.52 | L10: 385049.09 | M10: 434571.69 | N10: 340677.61 | O10: 444284.25 | P10: 731679.1 | Q10: 470875.67 | R10: 382893.1 | S10: 391077.23 | T10: 643771.56 | U10: 543188.63 | V10: 367910.31 | W10: 644069.28 | X10: 387314.2 | Y10: 398342.75 | Z10: 63949.908 | AA10: 40714.41 | AB10: 52095.289 | AC10: 62870.228 | AD10: 63999.999 | AE10: 62486.676 | AF10: 41007.139 | AG10: 39452.511 | AH10: 45941.093 | AI10: 32130.505 | AJ10: 47038.151 | AK10: 52027.089 | AL10: 51463.708 | AM10: 42795.848 | AN10: 61895.787 | AO10: 41690.249 | AP10: 45928.237 | AQ10: 73123.369 | AR10: 57881.526 | AS10: 62116.166 | AT10: 49569.897 | AU10: 43902.775 | AV10: 51366.465
A11: HILIC_neg_124_00772a5_29 | B11: 1032004.9 | C11: 933520.86 | D11: 1042667.2 | E11: 1199675 | F11: 1068256.4 | G11: 894251.6 | H11: 1148296.8 | I11: 1034554 | J11: 1208634.2 | K11: 952332.05 | L11: 1279592.2 | M11: 989471.03 | N11: 1214605.5 | O11: 1204209.1 | P11: 1076870.9 | Q11: 1132000.6 | R11: 1155855.8 | S11: 914645.62 | T11: 1233945.9 | U11: 1163494.4 | V11: 1146832.5 | W11: 1273827.2 | X11: 1237454.3 | Y11: 903668.15 | Z11: 21880.358 | AA11: 16059.782 | AB11: 91673.784 | AC11: 103920.43 | AD11: 111841.72 | AE11: 331549.56 | AF11: 7726.9367 | AG11: 312164.51 | AH11: 31802.872 | AI11: 24739.499 | AJ11: 40419.669 | AK11: 22654.373 | AL11: 98040.432 | AM11: 23989.717 | AN11: 209339.72 | AO11: 75550.095 | AP11: 120918.93 | AQ11: 263616.94 | AR11: 137186.59 | AS11: 156329.84 | AT11: 41971.774 | AU11: 152033.42 | AV11: 64151.171
A12: HILIC_neg_128_95963a3_171 | B12: 833098.17 | C12: 706530.82 | D12: 771230.46 | E12: 905445.93 | F12: 938741.12 | G12: 876238.68 | H12: 880945.27 | I12: 929447.22 | J12: 858120.03 | K12: 890282.09 | L12: 885617.53 | M12: 799650.19 | N12: 851267.02 | O12: 1053914.6 | P12: 888556.65 | Q12: 882159.81 | R12: 850631.12 | S12: 922801.83 | T12: 995393.62 | U12: 876595.83 | V12: 1001804.9 | W12: 967397.38 | X12: 893781.87 | Y12: 675477.93 | Z12: 494960.24 | AA12: 347479.25 | AB12: 363278.54 | AC12: 321463.48 | AD12: 450951.92 | AE12: 438719.21 | AF12: 408231 | AG12: 369927.23 | AH12: 479373.34 | AI12: 336097.79 | AJ12: 271456.45 | AK12: 457506.34 | AL12: 706369.99 | AM12: 464200.1 | AN12: 378869.73 | AO12: 375166.5 | AP12: 310532.96 | AQ12: 262506.11 | AR12: 309448.77 | AS12: 203331.23 | AT12: 322971.44 | AU12: 343496.85 | AV12: 348802.85
A13: HILIC_neg_130_06177a5_514 | B13: 319973.68 | C13: 294592.67 | D13: 312805.9 | E13: 347356.11 | F13: 394492.17 | G13: 281015.67 | H13: 361114.27 | I13: 388796.68 | J13: 351953.54 | K13: 298261.27 | L13: 358787.94 | M13: 355100.89 | N13: 347971.85 | O13: 290317.53 | P13: 312251.77 | Q13: 378803.88 | R13: 301928.63 | S13: 351220.16 | T13: 342982.64 | U13: 329895.94 | V13: 340289.15 | W13: 368126.04 | X13: 329407.88 | Y13: 231775.98 | Z13: 1455.3477 | AA13: 1683.1748 | AB13: 1677.51 | AC13: 13241.134 | AD13: 4587.7022 | AE13: 20006.975 | AF13: 127.40737 | AG13: 2187.8576 | AH13: 2160.6113 | AI13: 2605.8823 | AJ13: 4923.053 | AK13: 2164.2519 | AL13: 1206.0282 | AM13: 3835.6965 | AN13: 22178.705 | AO13: 7002.1597 | AP13: 7789.437 | AQ13: 16200.545 | AR13: 6087.6081 | AS13: 8968.9072 | AT13: 8930.0828 | AU13: 1197.2554 | AV13: 8665.413
... A1838: RP_pos_1568_1637a12_33 | B1838: 3000227.5 | C1838: 1911175.7 | D1838: 2652967.1 | E1838: 2870172.2 | F1838: 1779644.7 | G1838: 2882974.8 | H1838: 2155394.7 | I1838: 2585231.9 | J1838: 2132402.2 | K1838: 2085677.5 | L1838: 2369282.4 | M1838: 2678646.6 | N1838: 3241560.3 | O1838: 2806530.5 | P1838: 1886727.5 | Q1838: 2732479.5 | R1838: 2436754.5 | S1838: 1987600.2 | T1838: 2439589.1 | U1838: 2254745.4 | V1838: 2290678.3 | W1838: 2600588.9 | X1838: 2471182.7 | Y1838: 2014729.4 | Z1838: 2841.1368 | AA1838: 11937.616 | AB1838: 13406.302 | AC1838: 561.64905 | AD1838: 1095.5706 | AE1838: 25011.591 | AF1838: 18035.174 | AG1838: 12063.863 | AH1838: 43068.716 | AI1838: 34887.787 | AJ1838: 29278.886 | AK1838: 32575.12 | AL1838: 588.3354 | AM1838: 47205.729 | AN1838: 4323.5114 | AO1838: 16035.786 | AP1838: 6469.1906 | AQ1838: 43605.154 | AR1838: 7567.629 | AS1838: 0 | AT1838: 18487.069 | AU1838: 4484.2283 | AV1838: 0

Sheet Sample metadata
A1: SAMPLE_ID | B1: 3D'omics | C1: SAMPLE_TYPE | D1: Sample type | E1: PEN | F1: Diet | G1: GROUP | H1: TRIAL | I1: HILIC_neg_Datafile | J1: HILIC_pos_Datafile | K1: RP_neg_Datafile | L1: RP_pos_Datafile
A2: J011eJ | B2: J011 | C2: J | D2: Tissue | E2: P6 | F2: T2 | H2: 7-3 | I2: 240326ST_3DO_Swine Conventional_HILIC_neg_110 | J2: 240323ST_3DO_Swine Conventional_HILIC_pos_125 | K2: 240319ST_3DO_Swine Conventional_RP_neg_110 | L2: 240315ST_3DO_Swine Conventional_RP_pos_125
A3: J016eJ | B3: J016 | C3: J | D3: Tissue | E3: P3 | F3: T1 | H3: 7-3 | I3: 240326ST_3DO_Swine Conventional_HILIC_neg_111 | J3: 240323ST_3DO_Swine Conventional_HILIC_pos_126 | K3: 240319ST_3DO_Swine Conventional_RP_neg_111 | L3: 240315ST_3DO_Swine Conventional_RP_pos_126
A4: J005eJ | B4: J005 | C4: J | D4: Tissue | E4: P2 | F4: T1 | H4: 7-3 | I4: 240326ST_3DO_Swine Conventional_HILIC_neg_112 | J4: 240323ST_3DO_Swine Conventional_HILIC_pos_127 | K4: 240319ST_3DO_Swine Conventional_RP_neg_112 | L4: 240315ST_3DO_Swine Conventional_RP_pos_127
A5: J014eJ | B5: J014 | C5: J | D5: Tissue | E5: P6 | F5: T2 | H5: 7-3 | I5: 240326ST_3DO_Swine Conventional_HILIC_neg_113 | J5: 240323ST_3DO_Swine Conventional_HILIC_pos_128 | K5: 240319ST_3DO_Swine Conventional_RP_neg_113 | L5: 240315ST_3DO_Swine Conventional_RP_pos_128
A6: J003eJ | B6: J003 | C6: J | D6: Tissue | E6: P5 | F6: T2 | H6: 7-3 | I6: 240326ST_3DO_Swine Conventional_HILIC_neg_114 | J6: 240323ST_3DO_Swine Conventional_HILIC_pos_129 | K6: 240319ST_3DO_Swine Conventional_RP_neg_114 | L6: 240315ST_3DO_Swine Conventional_RP_pos_129
A7: J002eJ | B7: J002 | C7: J | D7: Tissue | E7: P2 | F7: T2 | H7: 7-3 | I7: 240326ST_3DO_Swine Conventional_HILIC_neg_115 | J7: 240323ST_3DO_Swine Conventional_HILIC_pos_130 | K7: 240319ST_3DO_Swine Conventional_RP_neg_115 | L7: 240315ST_3DO_Swine Conventional_RP_pos_130
A8: J012eJ | B8: J012 | C8: J | D8: Tissue | E8: P4 | F8: T2 | H8: 7-3 | I8: 240326ST_3DO_Swine Conventional_HILIC_neg_117 | J8: 240323ST_3DO_Swine Conventional_HILIC_pos_132 | K8: 240319ST_3DO_Swine Conventional_RP_neg_117 | L8: 240315ST_3DO_Swine Conventional_RP_pos_132
A9: J015eJ | B9: J015 | C9: J | D9: Tissue | E9: P1 | F9: T2 | H9: 7-3 | I9: 240326ST_3DO_Swine Conventional_HILIC_neg_118 | J9: 240323ST_3DO_Swine Conventional_HILIC_pos_133 | K9: 240319ST_3DO_Swine Conventional_RP_neg_118 | L9: 240315ST_3DO_Swine Conventional_RP_pos_133
A10: J018eJ | B10: J018 | C10: J | D10: Tissue | E10: P3 | F10: T2 | H10: 7-3 | I10: 240326ST_3DO_Swine Conventional_HILIC_neg_119 | J10: 240323ST_3DO_Swine Conventional_HILIC_pos_134 | K10: 240319ST_3DO_Swine Conventional_RP_neg_119 | L10: 240315ST_3DO_Swine Conventional_RP_pos_134
A11: J001eJ | B11: J001 | C11: J | D11: Tissue | E11: P1 | F11: T1 | H11: 7-3 | I11: 240326ST_3DO_Swine Conventional_HILIC_neg_120 | J11: 240323ST_3DO_Swine Conventional_HILIC_pos_135 | K11: 240319ST_3DO_Swine Conventional_RP_neg_120 | L11: 240315ST_3DO_Swine Conventional_RP_pos_135
A12: J017eJ | B12: J017 | C12: J | D12: Tissue | E12: P5 | F12: T1 | H12: 7-3 | I12: 240326ST_3DO_Swine Conventional_HILIC_neg_121 | J12: 240323ST_3DO_Swine Conventional_HILIC_pos_136 | K12: 240319ST_3DO_Swine Conventional_RP_neg_121 | L12: 240315ST_3DO_Swine Conventional_RP_pos_136
A13: J008eJ | B13: J008 | C13: J | D13: Tissue | E13: P5 | F13: T1 | H13: 7-3 | I13: 240326ST_3DO_Swine Conventional_HILIC_neg_122 | J13: 240323ST_3DO_Swine Conventional_HILIC_pos_137 | K13: 240319ST_3DO_Swine Conventional_RP_neg_122 | L13: 240315ST_3DO_Swine Conventional_RP_pos_137
... A48: J001eI | B48: J001 | C48: I | D48: Digesta | E48: P1 | F48: T1 | H48: 7-3 | I48: 240326ST_3DO_Swine Conventional_HILIC_neg_266 | J48: 240323ST_3DO_Swine Conventional_HILIC_pos_281 | K48: 240319ST_3DO_Swine Conventional_RP_neg_266 | L48: 240315ST_3DO_Swine Conventional_RP_pos_281

Sheet Annotations
A1: Feature_ID | B1: Split | C1: Average_Rt_min_ | D1: Average_Mz | E1: Curated_ID | F1: ID Level | G1: Class | H1: Formula | I1: KEGG ID | J1: Database ID
A2: HILIC_pos_282_1199a4_375 | B2: HILIC_pos | C2: 4.375 | D2: 282.1199 | E2: 1-Methyladenosine | F2: 1 | G2: Nucleosides, nucleotides, and analogues | H2: C11H15N5O4 | I2: C02494 | J2: HMDB0003331
A3: HILIC_pos_204_12305a3_15 | B3: HILIC_pos | C3: 3.15 | D3: 204.12305 | E3: Acetylcarnitine | F3: 1 | G3: Acylcarnitines | H3: C9H17NO4 | I3: C02571 | J3: HMDB0000201
A4: RP_pos_162_09132a4_953 | B4: RP_pos | C4: 4.953 | D4: 162.09132 | E4: Tryptophol | F4: 1 | G4: Indoles and derivatives | H4: C10H11NO | I4: C00955 | J4: HMDB0003447
A5: RP_pos_161_10786a2_57 | B5: RP_pos | C5: 2.57 | D5: 161.10786 | E5: Tryptamine | F5: 1 | G5: Indoles and derivatives | H5: C10H12N2 | I5: C00398 | J5: HMDB0000303
A6: RP_pos_177_10252a1_429 | B6: RP_pos | C6: 1.429 | D6: 177.10252 | E6: Serotonin | F6: 1 | G6: Indoles and derivatives | H6: C10H12N2O | I6: C00780 | J6: HMDB0000259
A7: RP_pos_209_09212a1_716 | B7: RP_pos | C7: 1.716 | D7: 209.09212 | E7: Kynurenine | F7: 1 | G7: Amino acids and derivatives | H7: C10H12N2O3 | I7: C00328 | J7: HMDB0000684
A8: RP_pos_268_10461a1_422 | B8: RP_pos | C8: 1.422 | D8: 268.10461 | E8: Adenosine | F8: 1 | G8: Nucleosides, nucleotides, and analogues | H8: C10H13N5O4 | I8: C00212 | J8: HMDB0000050
A9: HILIC_pos_284_09863a4_18 | B9: HILIC_pos | C9: 4.18 | D9: 284.09863 | E9: Guanosine | F9: 1 | G9: Nucleosides, nucleotides, and analogues | H9: C10H13N5O5 | I9: C00387 | J9: HMDB0000133
A10: HILIC_pos_348_07047a7_608 | B10: HILIC_pos | C10: 7.608 | D10: 348.07047 | E10: Adenylic acid (AMP) | F10: 1 | G10: Nucleosides, nucleotides, and analogues | H10: C10H14N5O7P | I10: C00020 | J10: HMDB0000045
A11: RP_neg_201_1131a6_45 | B11: RP_neg | C11: 6.45 | D11: 201.1131 | E11: Sebacic acid (aka decanedioic acid) | F11: 1 | G11: Fatty acyls | H11: C10H18O4 | I11: C08277 | J11: HMDB0000792
A12: RP_pos_218_13914a1_324 | B12: RP_pos | C12: 1.324 | D12: 218.13914 | E12: CAR 3:0 | F12: 1 | G12: Acylcarnitine | H12: C10H19NO4 | I12: C03017 | J12: HMDB0000824
A13: RP_pos_190_0498a3_236 | B13: RP_pos | C13: 3.236 | D13: 190.0498 | E13: Kynurenic acid | F13: 1 | G13: Quinolines and derivatives | H13: C10H7NO3 | I13: C01717 | J13: HMDB0000715
... A122: RP_neg_407_28064a7_729 | B122: RP_neg | C122: 7.729 | D122: 407.28064 | E122: Ursocholic acid | F122: 1 | G122: Bile acids | H122: HMDB0000917 | I122: C17644 | J122: HMDB0000917
A123: RP_pos_196_09697a2_095 | B123: RP_pos | C123: 2.095 | D123: 196.09697 | E123: Methyltyrosinate | F123: 2 | G123: Amino acids and derivatives | H123: C10H13NO3 | I123: NA
A124: HILIC_pos_229_11823a6_037 | B124: HILIC_pos | C124: 6.037 | D124: 229.11823 | E124: Prolylhydroxyproline | F124: 2 | G124: Amino acids and derivatives | H124: C10H16N2O4 | I124: NA | J124: HMDB0006695
A125: RP_neg_190_05119a3_946 | B125: RP_neg | C125: 3.946 | D125: 190.05119 | E125: Oxindole acetic acid | F125: 2 | G125: Oxindoles | H125: C10H9NO3 | I125: NA | J125: 3080590
A126: RP_pos_261_14429a3_098 | B126: RP_pos | C126: 3.098 | D126: 261.14429 | E126: Glutamylleucine | F126: 2 | G126: Amino acids and derivatives | H126: C11H20N2O5 | I126: NA | J126: HMDB0011171
A127: RP_pos_231_17026a2_873 | B127: RP_pos | C127: 2.873 | D127: 231.17026 | E127: Valyl leucine | F127: 2 | G127: Amino acids and derivatives | H127: C11H22N2O3 | I127: NA | J127: HMDB0029131
A128: RP_neg_229_14464a7_566 | B128: RP_neg | C128: 7.566 | D128: 229.14464 | E128: Dodecanedioic acid | F128: 2 | G128: Fatty acyls | H128: C12H22O4 | I128: C02678 | J128: HMDB0000623
A129: RP_pos_245_18558a3_236 | B129: RP_pos | C129: 3.236 | D129: 245.18558 | E129: Leucyl leucine | F129: 2 | G129: Amino acids and derivatives | H129: C12H24N2O3 | I129: C11332 | J129: HMDB0254039
A130: RP_pos_384_11499a2_426 | B130: RP_pos | C130: 2.426 | D130: 384.11499 | E130: Succinyladenosine | F130: 2 | G130: Purine nucleosides | H130: C14H17N5O8 | I130: NA | J130: HMDB0000912
A131: RP_neg_326_08826a3_049 | B131: RP_neg | C131: 3.049 | D131: 326.08826 | E131: Acetaminophen-glucuronide | F131: 2 | G131: Glycosides | H131: C14H17NO8 | I131: NA | J131: HMDB0010316
A132: RP_pos_279_13385a2_27 | B132: RP_pos | C132: 2.27 | D132: 279.13385 | E132: Tyrosyl proline | F132: 2 | G132: Amino acids and derivatives | H132: C14H18N2O4 | I132: NA | J132: HMDB0029113
A133: RP_pos_310_16568a3_005 | B133: RP_pos | C133: 3.005 | D133: 310.16568 | E133: Sinapine | F133: 2 | G133: Alkaloid | H133: C16H24NO5 | I133: C00933 | J133: HMDB0029379
A134: RP_neg_271_22803a9_611 | B134: RP_neg | C134: 9.611 | D134: 271.22803 | E134: Hydroxyhexadecanoic acid | F134: 2 | G134: Long-chain fatty acids | H134: C16H32O3 | I134: NA | J134: Ex: HMDB0031057
A135: RP_pos_283_26389a9_946 | B135: RP_pos | C135: 9.946 | D135: 283.26389 | E135: Oleic acid | F135: 2 | G135: Long-chain fatty acids | H135: C18H34O2 | I135: C00712 | J135: HMDB0000207
A136: RP_pos_300_29037a8_864 | B136: RP_pos | C136: 8.864 | D136: 300.29037 | E136: Sphingosine | F136: 2 | G136: Organonitrogen compounds | H136: C18H37NO2 | I136: C00319 | J136: HMDB0000252
A137: RP_pos_316_28494a8_545 | B137: RP_pos | C137: 8.545 | D137: 316.28494 | E137: Dehydrophytosphingosine | F137: 2 | G137: Organonitrogen compounds | H137: C18H37NO3 | I137: NA | J137: HMDB0038057
... A149: HILIC_pos_595_3504a1_164 | B149: HILIC_pos | C149: 1.164 | D149: 595.3504 | E149: Stercobilin | F149: 2 | G149: Bilirubins | H149: C33H46N4O6 | I149: C05793 | J149: HMDB0240259
A150: RP_neg_714_50787a12_177 | B150: RP_neg | C150: 12.177 | D150: 714.50787 | E150: PE 18:2/16:0 | F150: 2 | G150: Glycerophospholipids | H150: C39H74NO8P | I150: NA
A151: RP_pos_756_55469a11_89 | B151: RP_pos | C151: 11.89 | D151: 756.55469 | E151: PC(16:1/18:2) | F151: 2 | G151: Glycerophospholipids | H151: C42H78NO8P | I151: C00157 | J151: LMGP01010690
A152: RP_pos_810_60114a12_552 | B152: RP_pos | C152: 12.552 | D152: 810.60114 | E152: PC(18:1/20:3) | F152: 2 | G152: Glycerophospholipids | H152: C46H84NO8P | I152: C00157 | J152: LMGP01010904
A153: HILIC_pos_104_07069a5_307 | B153: HILIC_pos | C153: 5.307 | D153: 104.07069 | E153: Dimethylglycine | F153: 2 | G153: Amino acids and derivatives | H153: C4H9NO2 | I153: C01026 | J153: HMDB0000092
A154: RP_neg_117_05578a2_691 | B154: RP_neg | C154: 2.691 | D154: 117.05578 | E154: 3-Hydroisovaleric acid | F154: 2 | G154: Fatty acyls | H154: C5H10O3 | I154: C20827 | J154: HMDB0000754
A155: HILIC_neg_117_05537a0_773 | B155: HILIC_neg | C155: 0.773 | D155: 117.05537 | E155: 3-Hydroxyvaleric acid | F155: 2 | G155: Fatty acyls | H155: C5H10O3 | I155: NA | J155: HMDB0000531
A156: HILIC_pos_146_09247a3_906 | B156: HILIC_pos | C156: 3.906 | D156: 146.09247 | E156: 4-Guanidinobutanoic acid | F156: 2 | G156: Amino acids and derivatives | H156: C5H11N3O2 | I156: C01035 | J156: HMDB0003464
A157: HILIC_pos_166_05328a5_993 | B157: HILIC_pos | C157: 5.993 | D157: 166.05328 | E157: Methioninesulfoxide | F157: 2 | G157: Amino acids and derivatives | H157: C5H11NO3S | I157: C02989 | J157: HMDB0002005
A158: HILIC_pos_145_10831a3_283 | B158: HILIC_pos | C158: 3.283 | D158: 145.10831 | E158: 4-guanidinobutanamide | F158: 2 | G158: Amino acids and derivatives | H158: C5H12N4O | I158: C03078 | J158: C03078
A159: HILIC_pos_104_10734a1_583 | B159: HILIC_pos | C159: 1.583 | D159: 104.10734 | E159: Choline | F159: 2 | G159: Organonitrogen compounds | H159: C5H14NO | I159: C00114 | J159: HMDB0000097
...

Sheet Reordered Abundances
A1: Feature_ID | B1: Curated_ID | C1: J011eJ | D1: J016eJ | E1: J005eJ | F1: J014eJ | G1: J003eJ | H1: J002eJ | I1: J012eJ | J1: J015eJ | K1: J018eJ | L1: J001eJ | M1: J017eJ | N1: J008eJ | O1: J019eJ | P1: J013eJ | Q1: J006eJ | R1: J010eJ | S1: J020eJ | T1: J023eJ | U1: J024eJ | V1: J021eJ | W1: J009eJ | X1: J022eJ | Y1: J007eJ | Z1: J004eJ | AA1: J003eI | AB1: J006eI | AC1: J016eI | AD1: J017eI | AE1: J024eI | AF1: J022eI | AG1: J019eI | AH1: J021eI | AI1: J018eI | AJ1: J020eI | AK1: J012eI | AL1: J015eI | AM1: J009eI | AN1: J014eI | AO1: J023eI | AP1: J011eI | AQ1: J002eI | AR1: J013eI | AS1: J004eI | AT1: J008eI | AU1: J007eI | AV1: J005eI | AW1: J001eI
A2: HILIC_pos_282_1199a4_375 | B2: 1-Methyladenosine | C2: 330262.74 | D2: 420579.16 | E2: 284006.32 | F2: 245948.51 | G2: 237505.38 | H2: 269344.45 | I2: 271776.32 | J2: 199343.73 | K2: 255142.6 | L2: 372959.17 | M2: 224565.46 | N2: 216724.96 | O2: 302128.65 | P2: 248584.65 | Q2: 178887.35 | R2: 233806.68 | S2: 216169.01 | T2: 173114.4 | U2: 189193.99 | V2: 182218.83 | W2: 212522.59 | X2: 159274.91 | Y2: 217973.35 | Z2: 157111.01 | AA2: 13012.229 | AB2: 11639.95 | AC2: 32791.294 | AD2: 38595.789 | AE2: 15680.696 | AF2: 11806.032 | AG2: 8861.5329 | AH2: 3657.8751 | AI2: 12283.53 | AJ2: 8013.3155 | AK2: 71237.664 | AL2: 15078.01 | AM2: 8414.3148 | AN2: 21516.117 | AO2: 17202.885 | AP2: 15643.78 | AQ2: 48777.416 | AR2: 80125.863 | AS2: 33091.902 | AT2: 32142.526 | AU2: 44620.744 | AV2: 19509.515 | AW2: 60663.328
A3: HILIC_pos_204_12305a3_15 | B3: Acetylcarnitine | C3: 8618550.1 | D3: 6622918.8 | E3: 6625402.5 | F3: 7044269.4 | G3: 16297414 | H3: 5403728.1 | I3: 12322143 | J3: 8287988.8 | K3: 9739726.7 | L3: 12840837 | M3: 7438801.9 | N3: 5943260.4 | O3: 8697576.4 | P3: 11020031 | Q3: 13678342 | R3: 8089177.3 | S3: 13578455 | T3: 10800263 | U3: 8178139.3 | V3: 8395757.6 | W3: 11437471 | X3: 10329947 | Y3: 13160540 | Z3: 10543082 | AA3: 166686.69 | AB3: 193096.37 | AC3: 321066.76 | AD3: 709830.87 | AE3: 426232.03 | AF3: 492690.51 | AG3: 62332.796 | AH3: 51486.93 | AI3: 495932.3 | AJ3: 177052.35 | AK3: 929491 | AL3: 79904.198 | AM3: 81527.98 | AN3: 390487.68 | AO3: 756031.55 | AP3: 336746.34 | AQ3: 392272.31 | AR3: 1135376.8 | AS3: 340409.49 | AT3: 585455.73 | AU3: 406391.72 | AV3: 29539.557 | AW3: 448305.97
A4: RP_pos_162_09132a4_953 | B4: Tryptophol | C4: 52137.986 | D4: 183949.68 | E4: 36605.052 | F4: 54435.341 | G4: 25456.211 | H4: 28718.284 | I4: 68168.691 | J4: 241829.15 | K4: 59361.982 | L4: 32616.123 | M4: 40571.296 | N4: 34835.218 | O4: 306861.29 | P4: 48232.789 | Q4: 28920.02 | R4: 32697.259 | S4: 108752.47 | T4: 34211.853 | U4: 52392.797 | V4: 85274.194 | W4: 57615.316 | X4: 36904.603 | Y4: 71239.384 | Z4: 24872.343 | AA4: 17072.245 | AB4: 36214.829 | AC4: 250646.04 | AD4: 40984 | AE4: 38789.66 | AF4: 40207.088 | AG4: 535614.06 | AH4: 81541.225 | AI4: 59900.864 | AJ4: 143214.09 | AK4: 59970.037 | AL4: 235708.98 | AM4: 44903.143 | AN4: 44267.603 | AO4: 37075.639 | AP4: 46052.893 | AQ4: 27122.43 | AR4: 37768.428 | AS4: 24006.757 | AT4: 26536.617 | AU4: 61236.696 | AV4: 37575.272 | AW4: 30093.379
A5: RP_pos_161_10786a2_57 | B5: Tryptamine | C5: 79114.535 | D5: 1180030.4 | E5: 812553.28 | F5: 30222.93 | G5: 18247.144 | H5: 14821.564 | I5: 32773.668 | J5: 96497.372 | K5: 72052.517 | L5: 524730.91 | M5: 1444045.6 | N5: 295495.83 | O5: 312883.79 | P5: 810422.88 | Q5: 48866.153 | R5: 89639.932 | S5: 779125.07 | T5: 125702.54 | U5: 613463.78 | V5: 851559.54 | W5: 1227478.4 | X5: 150717.33 | Y5: 296961.49 | Z5: 535477.68 | AA5: 90915.707 | AB5: 151015.36 | AC5: 3036241.4 | AD5: 3416120.8 | AE5: 1876357.7 | AF5: 377343.8 | AG5: 1150231.3 | AH5: 2205249.2 | AI5: 193236.14 | AJ5: 1976519.3 | AK5: 90106.423 | AL5: 206802.43 | AM5: 3663032.4 | AN5: 10985.433 | AO5: 273582.92 | AP5: 279587.21 | AQ5: 69113.638 | AR5: 2248258.3 | AS5: 1662265.8 | AT5: 1603181.4 | AU5: 1024335.8 | AV5: 3026241.5 | AW5: 1906116.6
A6: RP_pos_177_10252a1_429 | B6: Serotonin | C6: 1526429.8 | D6: 968427.01 | E6: 722326.01 | F6: 1584948.1 | G6: 716182.61 | H6: 1300374.6 | I6: 971511.85 | J6: 1343288.7 | K6: 943851.03 | L6: 944692.37 | M6: 912163.46 | N6: 916264.92 | O6: 1762890.3 | P6: 1569892.7 | Q6: 882828.95 | R6: 1178330.1 | S6: 781551.01 | T6: 750359.46 | U6: 1005740.7 | V6: 1191677.9 | W6: 907135.52 | X6: 1471229.8 | Y6: 1542357.7 | Z6: 884926.01 | AA6: 26736.986 | AB6: 13787.111 | AC6: 26464.133 | AD6: 59716.485 | AE6: 41429.333 | AF6: 27565.882 | AG6: 7834.2431 | AH6: 27255.988 | AI6: 12535.354 | AJ6: 28769.815 | AK6: 7913.7771 | AL6: 8678.7559 | AM6: 82808.369 | AN6: 3179.6231 | AO6: 19661.113 | AP6: 9505.2923 | AQ6: 35401.224 | AR6: 66596.674 | AS6: 45201.988 | AT6: 55250.847 | AU6: 53920.228 | AV6: 71410.595 | AW6: 119881.49
A7: RP_pos_209_09212a1_716 | B7: Kynurenine | C7: 290797.95 | D7: 178962.21 | E7: 173096.13 | F7: 256846.54 | G7: 239766.12 | H7: 385040.96 | I7: 178849.46 | J7: 315994.4 | K7: 264520.43 | L7: 160489.2 | M7: 309314.31 | N7: 420645.75 | O7: 322827.61 | P7: 327043.21 | Q7: 312498.4 | R7: 338941.12 | S7: 264015.18 | T7: 210165.94 | U7: 294457.06 | V7: 207365.29 | W7: 174336.85 | X7: 198357.53 | Y7: 351241.38 | Z7: 279106.9 | AA7: 41451.588 | AB7: 35127.979 | AC7: 46443.742 | AD7: 67714.133 | AE7: 60276.346 | AF7: 86075.08 | AG7: 30370.272 | AH7: 49658.037 | AI7: 56507.828 | AJ7: 35482.754 | AK7: 50468.82 | AL7: 39735.381 | AM7: 27822.887 | AN7: 34647.392 | AO7: 80917.017 | AP7: 37896.084 | AQ7: 64712.081 | AR7: 61663.923 | AS7: 61729.91 | AT7: 63482.369 | AU7: 48034.204 | AV7: 32490.311 | AW7: 66639.83
A8: RP_pos_268_10461a1_422 | B8: Adenosine | C8: 3063063.8 | D8: 4490096.7 | E8: 4833831.1 | F8: 4699120 | G8: 4014695 | H8: 7045301 | I8: 4249138.6 | J8: 4243126.6 | K8: 5755927.7 | L8: 6237201.3 | M8: 4920598.9 | N8: 10773501 | O8: 3860822.3 | P8: 5501477.7 | Q8: 2620300.7 | R8: 5216190.7 | S8: 5023346.8 | T8: 5408605.9 | U8: 4594456.8 | V8: 3488543.8 | W8: 14408470 | X8: 2856382.6 | Y8: 4076026 | Z8: 3521781.7 | AA8: 1435396.1 | AB8: 1114572.9 | AC8: 993873.48 | AD8: 1053762.6 | AE8: 1308907.8 | AF8: 790805.96 | AG8: 1088563.1 | AH8: 1119255 | AI8: 1003517.6 | AJ8: 1204046.1 | AK8: 1175387.8 | AL8: 994915.03 | AM8: 960361.73 | AN8: 1695340.2 | AO8: 1171753.1 | AP8: 1320919.4 | AQ8: 1755104.4 | AR8: 1100212.6 | AS8: 746574.11 | AT8: 986880.6 | AU8: 1936230.7 | AV8: 1210654.1 | AW8: 979478.14
A9: HILIC_pos_284_09863a4_18 | B9: Guanosine | C9: 106086.35 | D9: 97447.143 | E9: 142154.14 | F9: 142755.06 | G9: 139382.25 | H9: 294007.57 | I9: 138315.05 | J9: 159321.08 | K9: 137419.69 | L9: 236893.94 | M9: 185703.77 | N9: 329881.1 | O9: 148589.07 | P9: 267955.14 | Q9: 170261.76 | R9: 165865.5 | S9: 222881.41 | T9: 262320.53 | U9: 219324.87 | V9: 131422.65 | W9: 214077.24 | X9: 190546.01 | Y9: 287439.65 | Z9: 152082.03 | AA9: 19911.238 | AB9: 5075.1403 | AC9: 7246.3967 | AD9: 16574.309 | AE9: 9450.6693 | AF9: 10462.974 | AG9: 5646.5862 | AH9: 8226.9931 | AI9: 9667.3689 | AJ9: 6987.9098 | AK9: 13075.823 | AL9: 7337.3672 | AM9: 11286.556 | AN9: 9598.6154 | AO9: 16598.083 | AP9: 16381.856 | AQ9: 14933.062 | AR9: 31994.409 | AS9: 13371.22 | AT9: 16958.584 | AU9: 25336.029 | AV9: 4672.4526 | AW9: 8442.2829
A10: HILIC_pos_348_07047a7_608 | B10: Adenylic acid (AMP) | C10: 241902.16 | D10: 151390.66 | E10: 298675.08 | F10: 281904.67 | G10: 189608.32 | H10: 240027.81 | I10: 267527.68 | J10: 146965.74 | K10: 222730.26 | L10: 202467.5 | M10: 227139.47 | N10: 303273.73 | O10: 258014.86 | P10: 374427.18 | Q10: 188719.21 | R10: 312037.03 | S10: 282800.04 | T10: 135263.55 | U10: 319859.96 | V10: 231406.8 | W10: 112863.4 | X10: 228418.2 | Y10: 338249.67 | Z10: 212458.79 | AA10: 5079.9871 | AB10: 5634.8348 | AC10: 9682.279 | AD10: 10400.063 | AE10: 12002.335 | AF10: 9431.5811 | AG10: 7260.7916 | AH10: 7658.9755 | AI10: 7587.5071 | AJ10: 5107.5185 | AK10: 4727.4129 | AL10: 7686.0238 | AM10: 7000.9215 | AN10: 6771.1119 | AO10: 1869.958 | AP10: 9195.5973 | AQ10: 7465.2633 | AR10: 4398.3469 | AS10: 8495.5419 | AT10: 7361.7529 | AU10: 15813.677 | AV10: 5283.578 | AW10: 3566.6947
A11: RP_neg_201_1131a6_45 | B11: Sebacic acid (aka decanedioic acid) | C11: 213094.11 | D11: 178836.04 | E11: 191867.78 | F11: 326486.84 | G11: 173528.32 | H11: 154716.86 | I11: 161544.26 | J11: 407441.33 | K11: 203992.1 | L11: 202360.6 | M11: 167244.71 | N11: 177118.49 | O11: 266506.05 | P11: 195670.12 | Q11: 249189.9 | R11: 179419.42 | S11: 306274.29 | T11: 198181.88 | U11: 141585.26 | V11: 261234.92 | W11: 154768.7 | X11: 198174.49 | Y11: 248410.48 | Z11: 185527.22 | AA11: 495636.15 | AB11: 528607.48 | AC11: 368807.81 | AD11: 298636.18 | AE11: 225932.54 | AF11: 326824.31 | AG11: 695833.13 | AH11: 543056.37 | AI11: 451511.75 | AJ11: 708770.52 | AK11: 268545.39 | AL11: 681337.14 | AM11: 350121.09 | AN11: 617195.37 | AO11: 375320.68 | AP11: 369592.56 | AQ11: 265615.2 | AR11: 300841.6 | AS11: 449717.95 | AT11: 333636.01 | AU11: 487735.63 | AV11: 513179.59 | AW11: 496707.71
A12: RP_pos_218_13914a1_324 | B12: CAR 3:0 | C12: 9298280 | D12: 4838132.1 | E12: 5069725.4 | F12: 6604843.4 | G12: 12123024 | H12: 8386036.2 | I12: 7077638.8 | J12: 7949893.5 | K12: 10526724 | L12: 5366557.5 | M12: 6209047.8 | N12: 6350500.3 | O12: 8867509 | P12: 4009662.3 | Q12: 6658500.4 | R12: 10356874 | S12: 7808962.8 | T12: 3624371.5 | U12: 4639128.1 | V12: 4337479.1 | W12: 5917602.1 | X12: 4444683 | Y12: 7033115.3 | Z12: 4461010.2 | AA12: 34510.76 | AB12: 37310.201 | AC12: 31039.266 | AD12: 127654.77 | AE12: 68893.6 | AF12: 43355.084 | AG12: 15816.495 | AH12: 25411.285 | AI12: 94385.196 | AJ12: 37149.942 | AK12: 132001.98 | AL12: 35387.935 | AM12: 19273.72 | AN12: 86563.321 | AO12: 90370.078 | AP12: 77645.467 | AQ12: 139606.07 | AR12: 216696.16 | AS12: 84182.746 | AT12: 92397.007 | AU12: 110986.5 | AV12: 15256.676 | AW12: 136314.29
A13: RP_pos_176_07085a4_942 | B13: 3-indoleacetic acid | C13: 515660.74 | D13: 2674578 | E13: 926494.45 | F13: 2449519.8 | G13: 1162971.9 | H13: 2158006.7 | I13: 3592699 | J13: 1705478.9 | K13: 3177663.9 | L13: 2616671.1 | M13: 3079853.9 | N13: 1476971.3 | O13: 830101.32 | P13: 2183964.9 | Q13: 3555972.7 | R13: 2012414.6 | S13: 1765845.8 | T13: 3864417.3 | U13: 4141360.9 | V13: 3679534.9 | W13: 1867185.1 | X13: 4499669.7 | Y13: 1440412.4 | Z13: 1974484 | AA13: 2145615.6 | AB13: 5521813.8 | AC13: 4906843.4 | AD13: 4814373.3 | AE13: 6402852.6 | AF13: 6930474.3 | AG13: 1532164.9 | AH13: 5790415.9 | AI13: 5331461.3 | AJ13: 2875952.6 | AK13: 5223112.7 | AL13: 2202248 | AM13: 3585888.6 | AN13: 3189272.2 | AO13: 6382427.3 | AP13: 807761.11 | AQ13: 3158337.8 | AR13: 3131361.2 | AS13: 3287266.7 | AT13: 2307409.4 | AU13: 1825444.5 | AV13: 1614128.1 | AW13: 5069037.9
... A189: RP_neg_271_22879a10_298 | B189: FA 16:0;O | C189: 5912478.2 | D189: 2513241.4 | E189: 4888783 | F189: 3715643.1 | G189: 3070035.3 | H189: 1704760.3 | I189: 2296770 | J189: 3235636.2 | K189: 2676772 | L189: 3366866.2 | M189: 3675040.3 | N189: 3050925.4 | O189: 3109346.6 | P189: 2941155.9 | Q189: 4360305.8 | R189: 3414288.3 | S189: 2882785.4 | T189: 1280970.9 | U189: 2101467.1 | V189: 2894007.5 | W189: 3234456.7 | X189: 1920117.8 | Y189: 3669934.9 | Z189: 4823884.2 | AA189: 8944496.2 | AB189: 12027323 | AC189: 6517037.4 | AD189: 7361171.5 | AE189: 6480932.9 | AF189: 5714209.5 | AG189: 6734961.6 | AH189: 6247642.1 | AI189: 7638709 | AJ189: 6399519.7 | AK189: 7410597.9 | AL189: 7013391.7 | AM189: 7394721.7 | AN189: 8187077.6 | AO189: 4521850.1 | AP189: 9557807 | AQ189: 4182054.8 | AR189: 8191370.3 | AS189: 10186767 | AT189: 6855807 | AU189: 9626041.8 | AV189: 10002987 | AW189: 6620560.7

Sheet Normalized Abundances
A1: Feature_ID | B1: Curated_ID | C1: J011eJ | D1: J016eJ | E1: J005eJ | F1: J014eJ | G1: J003eJ | H1: J002eJ | I1: J012eJ | J1: J015eJ | K1: J018eJ | L1: J001eJ | M1: J017eJ | N1: J008eJ | O1: J019eJ | P1: J013eJ | Q1: J006eJ | R1: J010eJ | S1: J020eJ | T1: J023eJ | U1: J024eJ | V1: J021eJ | W1: J009eJ | X1: J022eJ | Y1: J007eJ | Z1: J004eJ | AA1: J003eI | AB1: J006eI | AC1: J016eI | AD1: J017eI | AE1: J024eI | AF1: J022eI | AG1: J019eI | AH1: J021eI | AI1: J018eI | AJ1: J020eI | AK1: J012eI | AL1: J015eI | AM1: J009eI | AN1: J014eI | AO1: J023eI | AP1: J011eI | AQ1: J002eI | AR1: J013eI | AS1: J004eI | AT1: J008eI | AU1: J007eI | AV1: J005eI | AW1: J001eI
A2: HILIC_pos_282_1199a4_375 | B2: 1-Methyladenosine | C2: {=('Reordered Abundances'!C2-AVERAGE('Reordered Abundances'!$C2:$AW2))/STDEV('Reordered Abundances'!$C2:$AW2)} -> 1.6305372 | D2: {=('Reordered Abundances'!D2-AVERAGE('Reordered Abundances'!$C2:$AW2))/STDEV('Reordered Abundances'!$C2:$AW2)} -> 2.3912301 | E2: {=('Reordered Abundances'!E2-AVERAGE('Reordered Abundances'!$C2:$AW2))/STDEV('Reordered Abundances'!$C2:$AW2)} -> 1.2409411 | F2: {=('Reordered Abundances'!F2-AVERAGE('Reordered Abundances'!$C2:$AW2))/STDEV('Reordered Abundances'!$C2:$AW2)} -> 0.92039795 | G2: {=('Reordered Abundances'!G2-AVERAGE('Reordered Abundances'!$C2:$AW2))/STDEV('Reordered Abundances'!$C2:$AW2)} -> 0.84928548 | H2: {=('Reordered Abundances'!H2-AVERAGE('Reordered Abundances'!$C2:$AW2))/STDEV('Reordered Abundances'!$C2:$AW2)} -> 1.117451 | I2: {=('Reordered Abundances'!I2-AVERAGE('Reordered Abundances'!$C2:$AW2))/STDEV('Reordered Abundances'!$C2:$AW2)} -> 1.1379335 | J2: {=('Reordered Abundances'!J2-AVERAGE('Reordered Abundances'!$C2:$AW2))/STDEV('Reordered Abundances'!$C2:$AW2)} -> 0.52786774 | ... AW2: {=('Reordered Abundances'!AW2-AVERAGE('Reordered Abundances'!$C2:$AW2))/STDEV('Reordered Abundances'!$C2:$AW2)} -> -0.64017223
A3: HILIC_pos_204_12305a3_15 | B3: Acetylcarnitine | C3: {=('Reordered Abundances'!C3-AVERAGE('Reordered Abundances'!$C3:$AW3))/STDEV('Reordered Abundances'!$C3:$AW3)} -> 0.66371276 | D3: {=('Reordered Abundances'!D3-AVERAGE('Reordered Abundances'!$C3:$AW3))/STDEV('Reordered Abundances'!$C3:$AW3)} -> 0.27697709 | E3: {=('Reordered Abundances'!E3-AVERAGE('Reordered Abundances'!$C3:$AW3))/STDEV('Reordered Abundances'!$C3:$AW3)} -> 0.2774584 | F3: {=('Reordered Abundances'!F3-AVERAGE('Reordered Abundances'!$C3:$AW3))/STDEV('Reordered Abundances'!$C3:$AW3)} -> 0.35863109 | G3: {=('Reordered Abundances'!G3-AVERAGE('Reordered Abundances'!$C3:$AW3))/STDEV('Reordered Abundances'!$C3:$AW3)} -> 2.1518085 | H3: {=('Reordered Abundances'!H3-AVERAGE('Reordered Abundances'!$C3:$AW3))/STDEV('Reordered Abundances'!$C3:$AW3)} -> 0.040708716 | I3: {=('Reordered Abundances'!I3-AVERAGE('Reordered Abundances'!$C3:$AW3))/STDEV('Reordered Abundances'!$C3:$AW3)} -> 1.3814363 | J3: {=('Reordered Abundances'!J3-AVERAGE('Reordered Abundances'!$C3:$AW3))/STDEV('Reordered Abundances'!$C3:$AW3)} -> 0.5996529 | ... AW3: {=('Reordered Abundances'!AW3-AVERAGE('Reordered Abundances'!$C3:$AW3))/STDEV('Reordered Abundances'!$C3:$AW3)} -> -0.9196082
A4: RP_pos_162_09132a4_953 | B4: Tryptophol | C4: {=('Reordered Abundances'!C4-AVERAGE('Reordered Abundances'!$C4:$AW4))/STDEV('Reordered Abundances'!$C4:$AW4)} -> -0.28029757 | D4: {=('Reordered Abundances'!D4-AVERAGE('Reordered Abundances'!$C4:$AW4))/STDEV('Reordered Abundances'!$C4:$AW4)} -> 1.1059231 | E4: {=('Reordered Abundances'!E4-AVERAGE('Reordered Abundances'!$C4:$AW4))/STDEV('Reordered Abundances'!$C4:$AW4)} -> -0.44365239 | F4: {=('Reordered Abundances'!F4-AVERAGE('Reordered Abundances'!$C4:$AW4))/STDEV('Reordered Abundances'!$C4:$AW4)} -> -0.25613703 | G4: {=('Reordered Abundances'!G4-AVERAGE('Reordered Abundances'!$C4:$AW4))/STDEV('Reordered Abundances'!$C4:$AW4)} -> -0.56090113 | H4: {=('Reordered Abundances'!H4-AVERAGE('Reordered Abundances'!$C4:$AW4))/STDEV('Reordered Abundances'!$C4:$AW4)} -> -0.52659496 | I4: {=('Reordered Abundances'!I4-AVERAGE('Reordered Abundances'!$C4:$AW4))/STDEV('Reordered Abundances'!$C4:$AW4)} -> -0.11170786 | J4: {=('Reordered Abundances'!J4-AVERAGE('Reordered Abundances'!$C4:$AW4))/STDEV('Reordered Abundances'!$C4:$AW4)} -> 1.7146227 | ... AW4: {=('Reordered Abundances'!AW4-AVERAGE('Reordered Abundances'!$C4:$AW4))/STDEV('Reordered Abundances'!$C4:$AW4)} -> -0.51213353
A5: RP_pos_161_10786a2_57 | B5: Tryptamine | C5: {=('Reordered Abundances'!C5-AVERAGE('Reordered Abundances'!$C5:$AW5))/STDEV('Reordered Abundances'!$C5:$AW5)} -> -0.79491122 | D5: {=('Reordered Abundances'!D5-AVERAGE('Reordered Abundances'!$C5:$AW5))/STDEV('Reordered Abundances'!$C5:$AW5)} -> 0.30894401 | E5: {=('Reordered Abundances'!E5-AVERAGE('Reordered Abundances'!$C5:$AW5))/STDEV('Reordered Abundances'!$C5:$AW5)} -> -0.059514235 | F5: {=('Reordered Abundances'!F5-AVERAGE('Reordered Abundances'!$C5:$AW5))/STDEV('Reordered Abundances'!$C5:$AW5)} -> -0.84393337 | G5: {=('Reordered Abundances'!G5-AVERAGE('Reordered Abundances'!$C5:$AW5))/STDEV('Reordered Abundances'!$C5:$AW5)} -> -0.85594113 | H5: {=('Reordered Abundances'!H5-AVERAGE('Reordered Abundances'!$C5:$AW5))/STDEV('Reordered Abundances'!$C5:$AW5)} -> -0.85937585 | I5: {=('Reordered Abundances'!I5-AVERAGE('Reordered Abundances'!$C5:$AW5))/STDEV('Reordered Abundances'!$C5:$AW5)} -> -0.84137582 | J5: {=('Reordered Abundances'!J5-AVERAGE('Reordered Abundances'!$C5:$AW5))/STDEV('Reordered Abundances'!$C5:$AW5)} -> -0.77748198 | ... AW5: {=('Reordered Abundances'!AW5-AVERAGE('Reordered Abundances'!$C5:$AW5))/STDEV('Reordered Abundances'!$C5:$AW5)} -> 1.0369688
A6: RP_pos_177_10252a1_429 | B6: Serotonin | C6: {=('Reordered Abundances'!C6-AVERAGE('Reordered Abundances'!$C6:$AW6))/STDEV('Reordered Abundances'!$C6:$AW6)} -> 1.5908798 | D6: {=('Reordered Abundances'!D6-AVERAGE('Reordered Abundances'!$C6:$AW6))/STDEV('Reordered Abundances'!$C6:$AW6)} -> 0.64503127 | E6: {=('Reordered Abundances'!E6-AVERAGE('Reordered Abundances'!$C6:$AW6))/STDEV('Reordered Abundances'!$C6:$AW6)} -> 0.22787517 | F6: {=('Reordered Abundances'!F6-AVERAGE('Reordered Abundances'!$C6:$AW6))/STDEV('Reordered Abundances'!$C6:$AW6)} -> 1.6900719 | G6: {=('Reordered Abundances'!G6-AVERAGE('Reordered Abundances'!$C6:$AW6))/STDEV('Reordered Abundances'!$C6:$AW6)} -> 0.21746174 | H6: {=('Reordered Abundances'!H6-AVERAGE('Reordered Abundances'!$C6:$AW6))/STDEV('Reordered Abundances'!$C6:$AW6)} -> 1.2077026 | I6: {=('Reordered Abundances'!I6-AVERAGE('Reordered Abundances'!$C6:$AW6))/STDEV('Reordered Abundances'!$C6:$AW6)} -> 0.65026027 | J6: {=('Reordered Abundances'!J6-AVERAGE('Reordered Abundances'!$C6:$AW6))/STDEV('Reordered Abundances'!$C6:$AW6)} -> 1.2804445 | ... AW6: {=('Reordered Abundances'!AW6-AVERAGE('Reordered Abundances'!$C6:$AW6))/STDEV('Reordered Abundances'!$C6:$AW6)} -> -0.7933048
A7: RP_pos_209_09212a1_716 | B7: Kynurenine | C7: {=('Reordered Abundances'!C7-AVERAGE('Reordered Abundances'!$C7:$AW7))/STDEV('Reordered Abundances'!$C7:$AW7)} -> 1.0534443 | D7: {=('Reordered Abundances'!D7-AVERAGE('Reordered Abundances'!$C7:$AW7))/STDEV('Reordered Abundances'!$C7:$AW7)} -> 0.13569832 | E7: {=('Reordered Abundances'!E7-AVERAGE('Reordered Abundances'!$C7:$AW7))/STDEV('Reordered Abundances'!$C7:$AW7)} -> 0.087560167 | F7: {=('Reordered Abundances'!F7-AVERAGE('Reordered Abundances'!$C7:$AW7))/STDEV('Reordered Abundances'!$C7:$AW7)} -> 0.77483236 | G7: {=('Reordered Abundances'!G7-AVERAGE('Reordered Abundances'!$C7:$AW7))/STDEV('Reordered Abundances'!$C7:$AW7)} -> 0.63466709 | H7: {=('Reordered Abundances'!H7-AVERAGE('Reordered Abundances'!$C7:$AW7))/STDEV('Reordered Abundances'!$C7:$AW7)} -> 1.8268209 | I7: {=('Reordered Abundances'!I7-AVERAGE('Reordered Abundances'!$C7:$AW7))/STDEV('Reordered Abundances'!$C7:$AW7)} -> 0.13477313 | J7: {=('Reordered Abundances'!J7-AVERAGE('Reordered Abundances'!$C7:$AW7))/STDEV('Reordered Abundances'!$C7:$AW7)} -> 1.2602113 | ... AW7: {=('Reordered Abundances'!AW7-AVERAGE('Reordered Abundances'!$C7:$AW7))/STDEV('Reordered Abundances'!$C7:$AW7)} -> -0.78604108
A8: RP_pos_268_10461a1_422 | B8: Adenosine | C8: {=('Reordered Abundances'!C8-AVERAGE('Reordered Abundances'!$C8:$AW8))/STDEV('Reordered Abundances'!$C8:$AW8)} -> -0.062998069 | D8: {=('Reordered Abundances'!D8-AVERAGE('Reordered Abundances'!$C8:$AW8))/STDEV('Reordered Abundances'!$C8:$AW8)} -> 0.45964449 | E8: {=('Reordered Abundances'!E8-AVERAGE('Reordered Abundances'!$C8:$AW8))/STDEV('Reordered Abundances'!$C8:$AW8)} -> 0.58553522 | F8: {=('Reordered Abundances'!F8-AVERAGE('Reordered Abundances'!$C8:$AW8))/STDEV('Reordered Abundances'!$C8:$AW8)} -> 0.53619807 | G8: {=('Reordered Abundances'!G8-AVERAGE('Reordered Abundances'!$C8:$AW8))/STDEV('Reordered Abundances'!$C8:$AW8)} -> 0.28553138 | H8: {=('Reordered Abundances'!H8-AVERAGE('Reordered Abundances'!$C8:$AW8))/STDEV('Reordered Abundances'!$C8:$AW8)} -> 1.3954733 | I8: {=('Reordered Abundances'!I8-AVERAGE('Reordered Abundances'!$C8:$AW8))/STDEV('Reordered Abundances'!$C8:$AW8)} -> 0.37139497 | J8: {=('Reordered Abundances'!J8-AVERAGE('Reordered Abundances'!$C8:$AW8))/STDEV('Reordered Abundances'!$C8:$AW8)} -> 0.36919313 | ... AW8: {=('Reordered Abundances'!AW8-AVERAGE('Reordered Abundances'!$C8:$AW8))/STDEV('Reordered Abundances'!$C8:$AW8)} -> -0.82609928
A9: HILIC_pos_284_09863a4_18 | B9: Guanosine | C9: {=('Reordered Abundances'!C9-AVERAGE('Reordered Abundances'!$C9:$AW9))/STDEV('Reordered Abundances'!$C9:$AW9)} -> 0.032907469 | D9: {=('Reordered Abundances'!D9-AVERAGE('Reordered Abundances'!$C9:$AW9))/STDEV('Reordered Abundances'!$C9:$AW9)} -> -0.053470984 | E9: {=('Reordered Abundances'!E9-AVERAGE('Reordered Abundances'!$C9:$AW9))/STDEV('Reordered Abundances'!$C9:$AW9)} -> 0.39352864 | F9: {=('Reordered Abundances'!F9-AVERAGE('Reordered Abundances'!$C9:$AW9))/STDEV('Reordered Abundances'!$C9:$AW9)} -> 0.39953688 | G9: {=('Reordered Abundances'!G9-AVERAGE('Reordered Abundances'!$C9:$AW9))/STDEV('Reordered Abundances'!$C9:$AW9)} -> 0.36581413 | H9: {=('Reordered Abundances'!H9-AVERAGE('Reordered Abundances'!$C9:$AW9))/STDEV('Reordered Abundances'!$C9:$AW9)} -> 1.911824 | I9: {=('Reordered Abundances'!I9-AVERAGE('Reordered Abundances'!$C9:$AW9))/STDEV('Reordered Abundances'!$C9:$AW9)} -> 0.35514375 | J9: {=('Reordered Abundances'!J9-AVERAGE('Reordered Abundances'!$C9:$AW9))/STDEV('Reordered Abundances'!$C9:$AW9)} -> 0.56517099 | ... AW9: {=('Reordered Abundances'!AW9-AVERAGE('Reordered Abundances'!$C9:$AW9))/STDEV('Reordered Abundances'!$C9:$AW9)} -> -0.94337953
A10: HILIC_pos_348_07047a7_608 | B10: Adenylic acid (AMP) | C10: {=('Reordered Abundances'!C10-AVERAGE('Reordered Abundances'!$C10:$AW10))/STDEV('Reordered Abundances'!$C10:$AW10)} -> 0.91076075 | D10: {=('Reordered Abundances'!D10-AVERAGE('Reordered Abundances'!$C10:$AW10))/STDEV('Reordered Abundances'!$C10:$AW10)} -> 0.1974757 | E10: {=('Reordered Abundances'!E10-AVERAGE('Reordered Abundances'!$C10:$AW10))/STDEV('Reordered Abundances'!$C10:$AW10)} -> 1.3581655 | F10: {=('Reordered Abundances'!F10-AVERAGE('Reordered Abundances'!$C10:$AW10))/STDEV('Reordered Abundances'!$C10:$AW10)} -> 1.2260046 | G10: {=('Reordered Abundances'!G10-AVERAGE('Reordered Abundances'!$C10:$AW10))/STDEV('Reordered Abundances'!$C10:$AW10)} -> 0.49865385 | H10: {=('Reordered Abundances'!H10-AVERAGE('Reordered Abundances'!$C10:$AW10))/STDEV('Reordered Abundances'!$C10:$AW10)} -> 0.89598974 | I10: {=('Reordered Abundances'!I10-AVERAGE('Reordered Abundances'!$C10:$AW10))/STDEV('Reordered Abundances'!$C10:$AW10)} -> 1.1127053 | J10: {=('Reordered Abundances'!J10-AVERAGE('Reordered Abundances'!$C10:$AW10))/STDEV('Reordered Abundances'!$C10:$AW10)} -> 0.16260467 | ... AW10: {=('Reordered Abundances'!AW10-AVERAGE('Reordered Abundances'!$C10:$AW10))/STDEV('Reordered Abundances'!$C10:$AW10)} -> -0.96746604
A11: RP_neg_201_1131a6_45 | B11: Sebacic acid (aka decanedioic acid) | C11: {=('Reordered Abundances'!C11-AVERAGE('Reordered Abundances'!$C11:$AW11))/STDEV('Reordered Abundances'!$C11:$AW11)} -> -0.71116002 | D11: {=('Reordered Abundances'!D11-AVERAGE('Reordered Abundances'!$C11:$AW11))/STDEV('Reordered Abundances'!$C11:$AW11)} -> -0.92798991 | E11: {=('Reordered Abundances'!E11-AVERAGE('Reordered Abundances'!$C11:$AW11))/STDEV('Reordered Abundances'!$C11:$AW11)} -> -0.84550801 | F11: {=('Reordered Abundances'!F11-AVERAGE('Reordered Abundances'!$C11:$AW11))/STDEV('Reordered Abundances'!$C11:$AW11)} -> 0.0065374185 | G11: {=('Reordered Abundances'!G11-AVERAGE('Reordered Abundances'!$C11:$AW11))/STDEV('Reordered Abundances'!$C11:$AW11)} -> -0.96158408 | H11: {=('Reordered Abundances'!H11-AVERAGE('Reordered Abundances'!$C11:$AW11))/STDEV('Reordered Abundances'!$C11:$AW11)} -> -1.0806476 | I11: {=('Reordered Abundances'!I11-AVERAGE('Reordered Abundances'!$C11:$AW11))/STDEV('Reordered Abundances'!$C11:$AW11)} -> -1.0374349 | J11: {=('Reordered Abundances'!J11-AVERAGE('Reordered Abundances'!$C11:$AW11))/STDEV('Reordered Abundances'!$C11:$AW11)} -> 0.51892323 | ... AW11: {=('Reordered Abundances'!AW11-AVERAGE('Reordered Abundances'!$C11:$AW11))/STDEV('Reordered Abundances'!$C11:$AW11)} -> 1.0839176
A12: RP_pos_218_13914a1_324 | B12: CAR 3:0 | C12: {=('Reordered Abundances'!C12-AVERAGE('Reordered Abundances'!$C12:$AW12))/STDEV('Reordered Abundances'!$C12:$AW12)} -> 1.5552024 | D12: {=('Reordered Abundances'!D12-AVERAGE('Reordered Abundances'!$C12:$AW12))/STDEV('Reordered Abundances'!$C12:$AW12)} -> 0.36236225 | E12: {=('Reordered Abundances'!E12-AVERAGE('Reordered Abundances'!$C12:$AW12))/STDEV('Reordered Abundances'!$C12:$AW12)} -> 0.42430052 | F12: {=('Reordered Abundances'!F12-AVERAGE('Reordered Abundances'!$C12:$AW12))/STDEV('Reordered Abundances'!$C12:$AW12)} -> 0.83485872 | G12: {=('Reordered Abundances'!G12-AVERAGE('Reordered Abundances'!$C12:$AW12))/STDEV('Reordered Abundances'!$C12:$AW12)} -> 2.3106634 | H12: {=('Reordered Abundances'!H12-AVERAGE('Reordered Abundances'!$C12:$AW12))/STDEV('Reordered Abundances'!$C12:$AW12)} -> 1.3112282 | I12: {=('Reordered Abundances'!I12-AVERAGE('Reordered Abundances'!$C12:$AW12))/STDEV('Reordered Abundances'!$C12:$AW12)} -> 0.96130505 | J12: {=('Reordered Abundances'!J12-AVERAGE('Reordered Abundances'!$C12:$AW12))/STDEV('Reordered Abundances'!$C12:$AW12)} -> 1.1945844 | ... AW12: {=('Reordered Abundances'!AW12-AVERAGE('Reordered Abundances'!$C12:$AW12))/STDEV('Reordered Abundances'!$C12:$AW12)} -> -0.89511105
A13: RP_pos_176_07085a4_942 | B13: 3-indoleacetic acid | C13: {=('Reordered Abundances'!C13-AVERAGE('Reordered Abundances'!$C13:$AW13))/STDEV('Reordered Abundances'!$C13:$AW13)} -> -1.5723869 | D13: {=('Reordered Abundances'!D13-AVERAGE('Reordered Abundances'!$C13:$AW13))/STDEV('Reordered Abundances'!$C13:$AW13)} -> -0.25545192 | E13: {=('Reordered Abundances'!E13-AVERAGE('Reordered Abundances'!$C13:$AW13))/STDEV('Reordered Abundances'!$C13:$AW13)} -> -1.3217792 | F13: {=('Reordered Abundances'!F13-AVERAGE('Reordered Abundances'!$C13:$AW13))/STDEV('Reordered Abundances'!$C13:$AW13)} -> -0.39273695 | G13: {=('Reordered Abundances'!G13-AVERAGE('Reordered Abundances'!$C13:$AW13))/STDEV('Reordered Abundances'!$C13:$AW13)} -> -1.1775284 | H13: {=('Reordered Abundances'!H13-AVERAGE('Reordered Abundances'!$C13:$AW13))/STDEV('Reordered Abundances'!$C13:$AW13)} -> -0.57055933 | I13: {=('Reordered Abundances'!I13-AVERAGE('Reordered Abundances'!$C13:$AW13))/STDEV('Reordered Abundances'!$C13:$AW13)} -> 0.30459995 | J13: {=('Reordered Abundances'!J13-AVERAGE('Reordered Abundances'!$C13:$AW13))/STDEV('Reordered Abundances'!$C13:$AW13)} -> -0.84660033 | ... AW13: {=('Reordered Abundances'!AW13-AVERAGE('Reordered Abundances'!$C13:$AW13))/STDEV('Reordered Abundances'!$C13:$AW13)} -> 1.2051635
... A189: RP_neg_271_22879a10_298 | B189: FA 16:0;O | C189: {=('Reordered Abundances'!C189-AVERAGE('Reordered Abundances'!$C189:$AW189))/STDEV('Reordered Abundances'!$C189:$AW189)} -> 0.21894272 | D189: {=('Reordered Abundances'!D189-AVERAGE('Reordered Abundances'!$C189:$AW189))/STDEV('Reordered Abundances'!$C189:$AW189)} -> -1.060951 | E189: {=('Reordered Abundances'!E189-AVERAGE('Reordered Abundances'!$C189:$AW189))/STDEV('Reordered Abundances'!$C189:$AW189)} -> -0.16650294 | F189: {=('Reordered Abundances'!F189-AVERAGE('Reordered Abundances'!$C189:$AW189))/STDEV('Reordered Abundances'!$C189:$AW189)} -> -0.60821808 | G189: {=('Reordered Abundances'!G189-AVERAGE('Reordered Abundances'!$C189:$AW189))/STDEV('Reordered Abundances'!$C189:$AW189)} -> -0.85130479 | H189: {=('Reordered Abundances'!H189-AVERAGE('Reordered Abundances'!$C189:$AW189))/STDEV('Reordered Abundances'!$C189:$AW189)} -> -1.3653634 | I189: {=('Reordered Abundances'!I189-AVERAGE('Reordered Abundances'!$C189:$AW189))/STDEV('Reordered Abundances'!$C189:$AW189)} -> -1.1424576 | J189: {=('Reordered Abundances'!J189-AVERAGE('Reordered Abundances'!$C189:$AW189))/STDEV('Reordered Abundances'!$C189:$AW189)} -> -0.78895212 | ... AW189: {=('Reordered Abundances'!AW189-AVERAGE('Reordered Abundances'!$C189:$AW189))/STDEV('Reordered Abundances'!$C189:$AW189)} -> 0.48555269
